Workbook

Sheet amber
A1: Date | B1: BDN | C1: ME_cons | D1: F.vap_cons | E1: GE_cons | F1: BLR_cons | G1: ROB_cal | H1: ROB_cams | I1: Discrepancy | J1: Trim | K1: List | L1: Level_TK1 | M1: Vap_temp_TK1 | N1: Liq_temp_TK1 | O1: Press_TK1 | P1: Level_TK2 | Q1: Vap_temp_TK2 | R1: Liq_temp_TK2 | S1: Press_TK2 | T1: PKI | U1: MN | V1: Min_MN | W1: Molar_Mass | X1: Density | Y1: Consumptions
A2: 46113 | B2: 0 | C2: 0 | D2: 0 | E2: 5.24 | F2: 4.7 | G2: 179 | H2: 179 | I2: 0 | J2: -1 | K2: 0 | L2: 1.683 | M2: -113.2 | N2: -149.2 | O2: 1.17 | P2: 1.501 | Q2: -119.8 | R2: -149.1 | S2: 1.17 | T2: 1.7167259 | U2: 87 | V2: 70 | W2: 16.599672 | X2: 0.4116603 | Y2: =SUM(C2:F2) -> 9.94
A3: 46114 | B3: 0 | C3: 0 | D3: 0 | E3: 2.5 | F3: 0.65 | G3: 175.8 | H3: 166.6 | I3: 9.2 | J3: -1 | K3: 0 | L3: 1.655 | M3: -120.9 | N3: -149.5 | O3: 1.13 | P3: 1.484 | Q3: -116.2 | R3: -149.3 | S3: 1.13 | T3: 1.9024655 | U3: 86 | V3: 70 | W3: 16.603942 | X3: 0.41257639 | Y3: =SUM(C3:F3) -> 3.15
A4: 46115 | B4: 830 | C4: 0 | D4: 0 | E4: 3.2 | F4: 0.74 | G4: 1001.9 | H4: 167.1 | I4: 34.8 | J4: -1 | K4: 0 | L4: 1.637 | M4: -118.3 | N4: -150.1 | O4: 1.032 | P4: 1.467 | Q4: -114.7 | R4: -150 | S4: 1.033 | T4: 2.8911262 | U4: 81 | V4: 70 | W4: 17.065622 | X4: 0.42255728 | Y4: =SUM(C4:F4) -> 3.94
A5: 46116 | B5: 0 | C5: 0 | D5: 0 | E5: 1.8 | F5: 1.8 | G5: 998.3 | H5: 1018.7 | I5: -20.4 | J5: -1 | K5: 0 | L5: 5.054 | M5: -121.6 | N5: -153.7 | O5: 0.7 | P5: 6.146 | Q5: -123.4 | R5: -154.4 | S5: 0.7 | T5: 2.9020915 | U5: 81 | V5: 70 | W5: 17.069295 | X5: 0.43056804 | Y5: =SUM(C5:F5) -> 3.6
A6: 46117 | B6: 0 | C6: 0 | D6: 0 | E6: 3.5 | F6: 0.2 | G6: 994.6 | H6: 1011.8 | I6: -17.2 | J6: -1 | K6: 0 | L6: 5.018 | M6: -129.6 | N6: -153.7 | O6: 0.726 | P6: 6.126 | Q6: -152.8 | R6: -153.9 | S6: 0.726 | T6: 2.9125735 | U6: 81 | V6: 70 | W6: 17.073241 | X6: 0.43008976 | Y6: =SUM(C6:F6) -> 3.7
A7: 46118 | B7: 0 | C7: 6.51 | D7: 0 | E7: 3.7 | F7: 0.6 | G7: 983.8 | H7: 999 | I7: -15.2 | J7: -1 | K7: 0 | L7: 4.997 | M7: -143.4 | N7: -153.5 | O7: 0.735 | P7: 6.031 | Q7: -151.5 | R7: -153.7 | S7: 0.736 | T7: 2.9265961 | U7: 81 | V7: 70 | W7: 17.077667 | X7: 0.42978113 | Y7: =SUM(C7:F7) -> 10.81
A8: 46119 | B8: 0 | C8: 0 | D8: 0 | E8: 3.7 | F8: 0.9 | G8: 979.2 | H8: 993.1 | I8: -13.9 | J8: -1 | K8: 0 | L8: 4.981 | M8: -143.1 | N8: -153.7 | O8: 0.715 | P8: 5.985 | Q8: -150.7 | R8: -153.8 | S8: 0.716 | T8: 2.9409107 | U8: 81 | V8: 70 | W8: 17.082518 | X8: 0.43016848 | Y8: =SUM(C8:F8) -> 4.6
A9: 46120 | B9: 0 | C9: 0 | D9: 0 | E9: 3.7 | F9: 1 | G9: 974.5 | H9: 998.7 | I9: -24.2 | J9: -1 | K9: 0 | L9: 5.009 | M9: -140.7 | N9: -153.9 | O9: 0.694 | P9: 6 | Q9: -150.6 | R9: -153.9 | S9: 0.695 | T9: 2.9557758 | U9: 81 | V9: 70 | W9: 17.087538 | X9: 0.43056004 | Y9: =SUM(C9:F9) -> 4.7
A10: 46121 | B10: 0 | C10: 12.8 | D10: 0 | E10: 4.7 | F10: 0.3 | G10: 956.7 | H10: 977.4 | I10: -20.7 | J10: -1 | K10: 0 | L10: 4.986 | M10: -135.4 | N10: -153.6 | O10: 0.724 | P10: 5.833 | Q10: -149.2 | R10: -153.7 | S10: 0.724 | T10: 2.9719804 | U10: 81 | V10: 70 | W10: 17.09302 | X10: 0.4301831 | Y10: =SUM(C10:F10) -> 17.8
A11: 46122 | B11: 0 | C11: 14.03 | D11: 0 | E11: 4.9 | F11: 0 | G11: 937.8 | H11: 954.1 | I11: -16.3 | J11: -1 | K11: 0 | L11: 4.96 | M11: -131.7 | N11: -153.5 | O11: 0.747 | P11: 5.65 | Q11: -140 | R11: -153.5 | S11: 0.747 | T11: 2.9883822 | U11: 81 | V11: 70 | W11: 17.098444 | X11: 0.4299864 | Y11: =SUM(C11:F11) -> 18.93
A12: 46123 | B12: 0 | C12: 11.63 | D12: 0 | E12: 4.3 | F12: 0 | G12: 921.8 | H12: 937.6 | I12: -15.8 | J12: -1 | K12: 0 | L12: 4.965 | M12: -131.4 | N12: -153.1 | O12: 0.782 | P12: 5.505 | Q12: -140.6 | R12: -153.2 | S12: 0.783 | T12: 3.0030779 | U12: 81 | V12: 70 | W12: 17.103394 | X12: 0.42939859 | Y12: =SUM(C12:F12) -> 15.93
A13: 46124 | B13: 0 | C13: 13.99 | D13: 0 | E13: 3.8 | F13: 0 | G13: 904 | H13: 920.4 | I13: -16.4 | J13: -1 | K13: 0 | L13: 4.972 | M13: -130.4 | N13: -152.7 | O13: 0.883 | P13: 5.353 | Q13: -143.8 | R13: -152.8 | S13: 0.883 | T13: 3.0163261 | U13: 81 | V13: 70 | W13: 17.107852 | X13: 0.42869592 | Y13: =SUM(C13:F13) -> 17.79
... A33: 46144 | B33: 0 | C33: 0 | D33: 0 | E33: 3.4 | F33: 0.4 | G33: 590.9 | H33: 603 | I33: -12.1 | J33: -1 | K33: 0 | L33: 3.923 | M33: -129.1 | N33: -153.3 | O33: 0.72 | P33: 3.506 | Q33: -127 | R33: -153.5 | S33: 0.721 | T33: 3.6920378 | U33: 78 | V33: 70 | W33: 17.33515 | X33: 0.43461495 | Y33: =SUM(C33:F33) -> 3.8

Sheet amber_an
M1: 12 | N1: Date | O1: BDN | P1: ME_cons | Q1: F.vap_cons | R1: GE_cons | S1: BLR_cons | T1: ROB_cal | U1: ROB_cams | V1: Discrepancy | W1: Trim | X1: List | Y1: Level_TK1 | Z1: Vap_temp_TK1 | AA1: Liq_temp_TK1 | AB1: Press_TK1 | AC1: Level_TK2 | AD1: Vap_temp_TK2 | AE1: Liq_temp_TK2 | AF1: Press_TK2 | AG1: PKI | AH1: MN | AI1: Min_MN | AJ1: Molar_Mass | AK1: Density | AL1: CONSUMPTION
N2: {=INDEX(amber!A:A,$M$1+ROW(A2))} -> 46125 | O2: {=INDEX(amber!B:B,$M$1+ROW(B2))} -> 0 | P2: {=INDEX(amber!C:C,$M$1+ROW(C2))} -> 2.51 | Q2: {=INDEX(amber!D:D,$M$1+ROW(D2))} -> 0 | R2: {=INDEX(amber!E:E,$M$1+ROW(E2))} -> 3.4 | S2: {=INDEX(amber!F:F,$M$1+ROW(F2))} -> 0 | T2: {=INDEX(amber!G:G,$M$1+ROW(G2))} -> 898.1 | U2: {=INDEX(amber!H:H,$M$1+ROW(H2))} -> 914.1 | V2: {=INDEX(amber!I:I,$M$1+ROW(I2))} -> -16 | W2: {=INDEX(amber!J:J,$M$1+ROW(J2))} -> -1 | X2: {=INDEX(amber!K:K,$M$1+ROW(K2))} -> 0 | Y2: {=INDEX(amber!L:L,$M$1+ROW(L2))} -> 4.964 | Z2: {=INDEX(amber!M:M,$M$1+ROW(M2))} -> -134.7 | AA2: {=INDEX(amber!N:N,$M$1+ROW(N2))} -> -152.4 | AB2: {=INDEX(amber!O:O,$M$1+ROW(O2))} -> 0.929 | AC2: {=INDEX(amber!P:P,$M$1+ROW(P2))} -> 5.314 | AD2: {=INDEX(amber!Q:Q,$M$1+ROW(Q2))} -> -135.5 | AE2: {=INDEX(amber!R:R,$M$1+ROW(R2))} -> -152.5 | AF2: {=INDEX(amber!S:S,$M$1+ROW(S2))} -> 0.93 | AG2: {=INDEX(amber!T:T,$M$1+ROW(T2))} -> 3.0280222 | AH2: {=INDEX(amber!U:U,$M$1+ROW(U2))} -> 81 | AI2: {=INDEX(amber!V:V,$M$1+ROW(V2))} -> 70 | AJ2: {=INDEX(amber!W:W,$M$1+ROW(W2))} -> 17.11192 | AK2: {=INDEX(amber!X:X,$M$1+ROW(X2))} -> 0.42818641 | AL2: {=INDEX(amber!Y:Y,$M$1+ROW(Y2))} -> 5.91
N3: {=INDEX(amber!A:A,$M$1+ROW(A3))} -> 46126 | O3: {=INDEX(amber!B:B,$M$1+ROW(B3))} -> 0 | P3: {=INDEX(amber!C:C,$M$1+ROW(C3))} -> 6.02 | Q3: {=INDEX(amber!D:D,$M$1+ROW(D3))} -> 0 | R3: {=INDEX(amber!E:E,$M$1+ROW(E3))} -> 3.6 | S3: {=INDEX(amber!F:F,$M$1+ROW(F3))} -> 0.26 | T3: {=INDEX(amber!G:G,$M$1+ROW(G3))} -> 888.3 | U3: {=INDEX(amber!H:H,$M$1+ROW(H3))} -> 903.6 | V3: {=INDEX(amber!I:I,$M$1+ROW(I3))} -> -15.3 | W3: {=INDEX(amber!J:J,$M$1+ROW(J3))} -> -1 | X3: {=INDEX(amber!K:K,$M$1+ROW(K3))} -> 0 | Y3: {=INDEX(amber!L:L,$M$1+ROW(L3))} -> 4.866 | Z3: {=INDEX(amber!M:M,$M$1+ROW(M3))} -> -139.9 | AA3: {=INDEX(amber!N:N,$M$1+ROW(N3))} -> -152 | AB3: {=INDEX(amber!O:O,$M$1+ROW(O3))} -> 0.931 | AC3: {=INDEX(amber!P:P,$M$1+ROW(P3))} -> 5.331 | AD3: {=INDEX(amber!Q:Q,$M$1+ROW(Q3))} -> -131.6 | AE3: {=INDEX(amber!R:R,$M$1+ROW(R3))} -> -152.1 | AF3: {=INDEX(amber!S:S,$M$1+ROW(S3))} -> 0.931 | AG3: {=INDEX(amber!T:T,$M$1+ROW(T3))} -> 3.042143 | AH3: {=INDEX(amber!U:U,$M$1+ROW(U3))} -> 81 | AI3: {=INDEX(amber!V:V,$M$1+ROW(V3))} -> 70 | AJ3: {=INDEX(amber!W:W,$M$1+ROW(W3))} -> 17.11653 | AK3: {=INDEX(amber!X:X,$M$1+ROW(X3))} -> 0.42749557 | AL3: {=INDEX(amber!Y:Y,$M$1+ROW(Y3))} -> 9.88
N4: {=INDEX(amber!A:A,$M$1+ROW(A4))} -> 46127 | O4: {=INDEX(amber!B:B,$M$1+ROW(B4))} -> 0 | P4: {=INDEX(amber!C:C,$M$1+ROW(C4))} -> 13.5 | Q4: {=INDEX(amber!D:D,$M$1+ROW(D4))} -> 0 | R4: {=INDEX(amber!E:E,$M$1+ROW(E4))} -> 5.2 | S4: {=INDEX(amber!F:F,$M$1+ROW(F4))} -> 17.9 | T4: {=INDEX(amber!G:G,$M$1+ROW(G4))} -> 851.7 | U4: {=INDEX(amber!H:H,$M$1+ROW(H4))} -> 871 | V4: {=INDEX(amber!I:I,$M$1+ROW(I4))} -> -19.3 | W4: {=INDEX(amber!J:J,$M$1+ROW(J4))} -> -1 | X4: {=INDEX(amber!K:K,$M$1+ROW(K4))} -> 0 | Y4: {=INDEX(amber!L:L,$M$1+ROW(L4))} -> 4.584 | Z4: {=INDEX(amber!M:M,$M$1+ROW(M4))} -> -139.7 | AA4: {=INDEX(amber!N:N,$M$1+ROW(N4))} -> -153 | AB4: {=INDEX(amber!O:O,$M$1+ROW(O4))} -> 0.763 | AC4: {=INDEX(amber!P:P,$M$1+ROW(P4))} -> 5.278 | AD4: {=INDEX(amber!Q:Q,$M$1+ROW(Q4))} -> -141.2 | AE4: {=INDEX(amber!R:R,$M$1+ROW(R4))} -> -153.1 | AF4: {=INDEX(amber!S:S,$M$1+ROW(S4))} -> 0.763 | AG4: {=INDEX(amber!T:T,$M$1+ROW(T4))} -> 3.128872 | AH4: {=INDEX(amber!U:U,$M$1+ROW(U4))} -> 80 | AI4: {=INDEX(amber!V:V,$M$1+ROW(V4))} -> 70 | AJ4: {=INDEX(amber!W:W,$M$1+ROW(W4))} -> 17.145636 | AK4: {=INDEX(amber!X:X,$M$1+ROW(X4))} -> 0.43007072 | AL4: {=INDEX(amber!Y:Y,$M$1+ROW(Y4))} -> 36.6
N5: {=INDEX(amber!A:A,$M$1+ROW(A5))} -> 46128 | O5: {=INDEX(amber!B:B,$M$1+ROW(B5))} -> 0 | P5: {=INDEX(amber!C:C,$M$1+ROW(C5))} -> 15.6 | Q5: {=INDEX(amber!D:D,$M$1+ROW(D5))} -> 0 | R5: {=INDEX(amber!E:E,$M$1+ROW(E5))} -> 4.4 | S5: {=INDEX(amber!F:F,$M$1+ROW(F5))} -> 6.9 | T5: {=INDEX(amber!G:G,$M$1+ROW(G5))} -> 824.8 | U5: {=INDEX(amber!H:H,$M$1+ROW(H5))} -> 842.5 | V5: {=INDEX(amber!I:I,$M$1+ROW(I5))} -> -17.7 | W5: {=INDEX(amber!J:J,$M$1+ROW(J5))} -> -1 | X5: {=INDEX(amber!K:K,$M$1+ROW(K5))} -> 0 | Y5: {=INDEX(amber!L:L,$M$1+ROW(L5))} -> 4.358 | Z5: {=INDEX(amber!M:M,$M$1+ROW(M5))} -> -152 | AA5: {=INDEX(amber!N:N,$M$1+ROW(N5))} -> -152.6 | AB5: {=INDEX(amber!O:O,$M$1+ROW(O5))} -> 0.855 | AC5: {=INDEX(amber!P:P,$M$1+ROW(P5))} -> 5.254 | AD5: {=INDEX(amber!Q:Q,$M$1+ROW(Q5))} -> -151.7 | AE5: {=INDEX(amber!R:R,$M$1+ROW(R5))} -> -152.7 | AF5: {=INDEX(amber!S:S,$M$1+ROW(S5))} -> 0.856 | AG5: {=INDEX(amber!T:T,$M$1+ROW(T5))} -> 3.1736035 | AH5: {=INDEX(amber!U:U,$M$1+ROW(U5))} -> 80 | AI5: {=INDEX(amber!V:V,$M$1+ROW(V5))} -> 70 | AJ5: {=INDEX(amber!W:W,$M$1+ROW(W5))} -> 17.16075 | AK5: {=INDEX(amber!X:X,$M$1+ROW(X5))} -> 0.42959232 | AL5: {=INDEX(amber!Y:Y,$M$1+ROW(Y5))} -> 26.9
N6: {=INDEX(amber!A:A,$M$1+ROW(A6))} -> 46129 | O6: {=INDEX(amber!B:B,$M$1+ROW(B6))} -> 0 | P6: {=INDEX(amber!C:C,$M$1+ROW(C6))} -> 16 | Q6: {=INDEX(amber!D:D,$M$1+ROW(D6))} -> 0 | R6: {=INDEX(amber!E:E,$M$1+ROW(E6))} -> 3.8 | S6: {=INDEX(amber!F:F,$M$1+ROW(F6))} -> 0 | T6: {=INDEX(amber!G:G,$M$1+ROW(G6))} -> 805 | U6: {=INDEX(amber!H:H,$M$1+ROW(H6))} -> 825.9 | V6: {=INDEX(amber!I:I,$M$1+ROW(I6))} -> -20.9 | W6: {=INDEX(amber!J:J,$M$1+ROW(J6))} -> -1 | X6: {=INDEX(amber!K:K,$M$1+ROW(K6))} -> 0 | Y6: {=INDEX(amber!L:L,$M$1+ROW(L6))} -> 4.226 | Z6: {=INDEX(amber!M:M,$M$1+ROW(M6))} -> -151.1 | AA6: {=INDEX(amber!N:N,$M$1+ROW(N6))} -> -151.8 | AB6: {=INDEX(amber!O:O,$M$1+ROW(O6))} -> 0.963 | AC6: {=INDEX(amber!P:P,$M$1+ROW(P6))} -> 5.261 | AD6: {=INDEX(amber!Q:Q,$M$1+ROW(Q6))} -> -151 | AE6: {=INDEX(amber!R:R,$M$1+ROW(R6))} -> -151.9 | AF6: {=INDEX(amber!S:S,$M$1+ROW(S6))} -> 0.963 | AG6: {=INDEX(amber!T:T,$M$1+ROW(T6))} -> 3.1890966 | AH6: {=INDEX(amber!U:U,$M$1+ROW(U6))} -> 80 | AI6: {=INDEX(amber!V:V,$M$1+ROW(V6))} -> 70 | AJ6: {=INDEX(amber!W:W,$M$1+ROW(W6))} -> 17.166108 | AK6: {=INDEX(amber!X:X,$M$1+ROW(X6))} -> 0.42812924 | AL6: {=INDEX(amber!Y:Y,$M$1+ROW(Y6))} -> 19.8
N7: {=INDEX(amber!A:A,$M$1+ROW(A7))} -> 46130 | O7: {=INDEX(amber!B:B,$M$1+ROW(B7))} -> 0 | P7: {=INDEX(amber!C:C,$M$1+ROW(C7))} -> 17.4 | Q7: {=INDEX(amber!D:D,$M$1+ROW(D7))} -> 0 | R7: {=INDEX(amber!E:E,$M$1+ROW(E7))} -> 3.6 | S7: {=INDEX(amber!F:F,$M$1+ROW(F7))} -> 0 | T7: {=INDEX(amber!G:G,$M$1+ROW(G7))} -> 784 | U7: {=INDEX(amber!H:H,$M$1+ROW(H7))} -> 806.8 | V7: {=INDEX(amber!I:I,$M$1+ROW(I7))} -> -22.8 | W7: {=INDEX(amber!J:J,$M$1+ROW(J7))} -> -1 | X7: {=INDEX(amber!K:K,$M$1+ROW(K7))} -> 0 | Y7: {=INDEX(amber!L:L,$M$1+ROW(L7))} -> 4.351 | Z7: {=INDEX(amber!M:M,$M$1+ROW(M7))} -> -148.9 | AA7: {=INDEX(amber!N:N,$M$1+ROW(N7))} -> -151 | AB7: {=INDEX(amber!O:O,$M$1+ROW(O7))} -> 1.071 | AC7: {=INDEX(amber!P:P,$M$1+ROW(P7))} -> 4.986 | AD7: {=INDEX(amber!Q:Q,$M$1+ROW(Q7))} -> -150.3 | AE7: {=INDEX(amber!R:R,$M$1+ROW(R7))} -> -151.1 | AF7: {=INDEX(amber!S:S,$M$1+ROW(S7))} -> 1.071 | AG7: {=INDEX(amber!T:T,$M$1+ROW(T7))} -> 3.204368 | AH7: {=INDEX(amber!U:U,$M$1+ROW(U7))} -> 80 | AI7: {=INDEX(amber!V:V,$M$1+ROW(V7))} -> 70 | AJ7: {=INDEX(amber!W:W,$M$1+ROW(W7))} -> 17.171268 | AK7: {=INDEX(amber!X:X,$M$1+ROW(X7))} -> 0.42666688 | AL7: {=INDEX(amber!Y:Y,$M$1+ROW(Y7))} -> 21
N8: {=INDEX(amber!A:A,$M$1+ROW(A8))} -> 46131 | O8: {=INDEX(amber!B:B,$M$1+ROW(B8))} -> 0 | P8: {=INDEX(amber!C:C,$M$1+ROW(C8))} -> 0 | Q8: {=INDEX(amber!D:D,$M$1+ROW(D8))} -> 0 | R8: {=INDEX(amber!E:E,$M$1+ROW(E8))} -> 3.9 | S8: {=INDEX(amber!F:F,$M$1+ROW(F8))} -> 0.83 | T8: {=INDEX(amber!G:G,$M$1+ROW(G8))} -> 779.2 | U8: {=INDEX(amber!H:H,$M$1+ROW(H8))} -> 797.7 | V8: {=INDEX(amber!I:I,$M$1+ROW(I8))} -> -18.5 | W8: {=INDEX(amber!J:J,$M$1+ROW(J8))} -> -1 | X8: {=INDEX(amber!K:K,$M$1+ROW(K8))} -> 0 | Y8: {=INDEX(amber!L:L,$M$1+ROW(L8))} -> 4.296 | Z8: {=INDEX(amber!M:M,$M$1+ROW(M8))} -> -142.3 | AA8: {=INDEX(amber!N:N,$M$1+ROW(N8))} -> -151.2 | AB8: {=INDEX(amber!O:O,$M$1+ROW(O8))} -> 1.038 | AC8: {=INDEX(amber!P:P,$M$1+ROW(P8))} -> 4.953 | AD8: {=INDEX(amber!Q:Q,$M$1+ROW(Q8))} -> -149.2 | AE8: {=INDEX(amber!R:R,$M$1+ROW(R8))} -> -151.3 | AF8: {=INDEX(amber!S:S,$M$1+ROW(S8))} -> 1.038 | AG8: {=INDEX(amber!T:T,$M$1+ROW(T8))} -> 3.2248629 | AH8: {=INDEX(amber!U:U,$M$1+ROW(U8))} -> 80 | AI8: {=INDEX(amber!V:V,$M$1+ROW(V8))} -> 70 | AJ8: {=INDEX(amber!W:W,$M$1+ROW(W8))} -> 17.178095 | AK8: {=INDEX(amber!X:X,$M$1+ROW(X8))} -> 0.42719735 | AL8: {=INDEX(amber!Y:Y,$M$1+ROW(Y8))} -> 4.73
N9: {=INDEX(amber!A:A,$M$1+ROW(A9))} -> 46132 | O9: {=INDEX(amber!B:B,$M$1+ROW(B9))} -> 0 | P9: {=INDEX(amber!C:C,$M$1+ROW(C9))} -> 0 | Q9: {=INDEX(amber!D:D,$M$1+ROW(D9))} -> 0 | R9: {=INDEX(amber!E:E,$M$1+ROW(E9))} -> 4.7 | S9: {=INDEX(amber!F:F,$M$1+ROW(F9))} -> 1 | T9: {=INDEX(amber!G:G,$M$1+ROW(G9))} -> 773.5 | U9: {=INDEX(amber!H:H,$M$1+ROW(H9))} -> 771.6 | V9: {=INDEX(amber!I:I,$M$1+ROW(I9))} -> 1.9 | W9: {=INDEX(amber!J:J,$M$1+ROW(J9))} -> -1 | X9: {=INDEX(amber!K:K,$M$1+ROW(K9))} -> 0 | Y9: {=INDEX(amber!L:L,$M$1+ROW(L9))} -> 4.175 | Z9: {=INDEX(amber!M:M,$M$1+ROW(M9))} -> -139.3 | AA9: {=INDEX(amber!N:N,$M$1+ROW(N9))} -> -151.5 | AB9: {=INDEX(amber!O:O,$M$1+ROW(O9))} -> 0.979 | AC9: {=INDEX(amber!P:P,$M$1+ROW(P9))} -> 4.83 | AD9: {=INDEX(amber!Q:Q,$M$1+ROW(Q9))} -> -147.5 | AE9: {=INDEX(amber!R:R,$M$1+ROW(R9))} -> -151.7 | AF9: {=INDEX(amber!S:S,$M$1+ROW(S9))} -> 0.979 | AG9: {=INDEX(amber!T:T,$M$1+ROW(T9))} -> 3.2501195 | AH9: {=INDEX(amber!U:U,$M$1+ROW(U9))} -> 80 | AI9: {=INDEX(amber!V:V,$M$1+ROW(V9))} -> 70 | AJ9: {=INDEX(amber!W:W,$M$1+ROW(W9))} -> 17.186421 | AK9: {=INDEX(amber!X:X,$M$1+ROW(X9))} -> 0.42806205 | AL9: {=INDEX(amber!Y:Y,$M$1+ROW(Y9))} -> 5.7

Sheet topaz
A1: Date | B1: BDN | C1: ME_cons | D1: F.vap_cons | E1: GE_cons | F1: BLR_cons | G1: ROB_cal | H1: ROB_cams | I1: Discrepancy | J1: Trim | K1: List | L1: Level_TK1 | M1: Vap_temp_TK1 | N1: Liq_temp_TK1 | O1: Press_TK1 | P1: Level_TK2 | Q1: Vap_temp_TK2 | R1: Liq_temp_TK2 | S1: Press_TK2 | T1: PKI | U1: MN | V1: Min_MN | W1: Molar_Mass | X1: Density | Y1: Consumptions
A2: 46113 | B2: 0 | C2: 0 | D2: 0 | E2: 3.5 | F2: 2.4 | G2: 150 | H2: 150 | I2: 0 | J2: -1 | K2: 0 | L2: 1.142 | M2: -105.1 | N2: -148.1 | O2: 1.24 | P2: 1.567 | Q2: -112.3 | R2: -148.5 | S2: 1.24 | T2: 1.7236508 | U2: 87 | V2: 70 | W2: 16.601849 | X2: 0.41193258 | Y2: =SUM(C2:F2) -> 5.9
A3: 46114 | B3: 0 | C3: 0 | D3: 0 | E3: 3.2 | F3: 1.1 | G3: 145.7 | H3: 131.2 | I3: 14.5 | J3: -1 | K3: 0 | L3: 1.113 | M3: -105.5 | N3: -149.1 | O3: 1.09 | P3: 1.542 | Q3: -112.1 | R3: -149.6 | S3: 1.09 | T3: 1.4672459 | U3: 88 | V3: 70 | W3: 16.629675 | X3: 0.41280021 | Y3: =SUM(C3:F3) -> 4.3
A4: 46115 | B4: 1226.868 | C4: 0 | D4: 0 | E4: 1.7 | F4: 0.7 | G4: 1370.2 | H4: 166.7 | I4: 3.5 | J4: -1 | K4: 0 | L4: 1.567 | M4: -110.6 | N4: -147.9 | O4: 1.14 | P4: 1.567 | Q4: -104.8 | R4: -148.9 | S4: 1.14 | T4: 2.4761607 | U4: 83 | V4: 70 | W4: 16.760812 | X4: 0.41575421 | Y4: =SUM(C4:F4) -> 2.4
A5: 46116 | B5: 0 | C5: 0 | D5: 0 | E5: 3.7 | F5: 0.8 | G5: 1365.7 | H5: 1377.5 | I5: -11.8 | J5: -1 | K5: 0 | L5: 7.452 | M5: -154 | N5: -155 | O5: 0.716 | P5: 7.586 | Q5: -154 | R5: -154.4 | S5: 0.716 | T5: 2.4853995 | U5: 83 | V5: 70 | W5: 16.763076 | X5: 0.42517804 | Y5: =SUM(C5:F5) -> 4.5
A6: 46117 | B6: 0 | C6: 0 | D6: 0 | E6: 0.2 | F6: 1.8 | G6: 1363.7 | H6: 1376.7 | I6: -13 | J6: -1 | K6: 0 | L6: 7.504 | M6: -154 | N6: -154.1 | O6: 0.713 | P6: 7.587 | Q6: -153.9 | R6: -153.8 | S6: 0.715 | T6: 2.4888998 | U6: 83 | V6: 70 | W6: 16.764156 | X6: 0.42362848 | Y6: =SUM(C6:F6) -> 2
A7: 46118 | B7: 0 | C7: 0 | D7: 0 | E7: 2.7 | F7: 4.5 | G7: 1356.5 | H7: 1373 | I7: -16.5 | J7: -1 | K7: 0 | L7: 7.508 | M7: -154 | N7: -153.9 | O7: 0.714 | P7: 7.541 | Q7: -153.9 | R7: -153.8 | S7: 0.714 | T7: 2.5026357 | U7: 83 | V7: 70 | W7: 16.767965 | X7: 0.42349739 | Y7: =SUM(C7:F7) -> 7.2
A8: 46119 | B8: 0 | C8: 0 | D8: 0 | E8: 3.2 | F8: 0.9 | G8: 1352.4 | H8: 1362.3 | I8: -9.9 | J8: -1 | K8: 0 | L8: 7.445 | M8: -153.9 | N8: -153.8 | O8: 0.722 | P8: 7.47 | Q8: -153.9 | R8: -153.8 | S8: 0.721 | T8: 2.5102875 | U8: 83 | V8: 70 | W8: 16.770179 | X8: 0.42343966 | Y8: =SUM(C8:F8) -> 4.1
A9: 46120 | B9: 0 | C9: 1.1 | D9: 0 | E9: 3.3 | F9: 0.9 | G9: 1347.1 | H9: 1357.4 | I9: -10.3 | J9: -1 | K9: 0 | L9: 7.435 | M9: -153.7 | N9: -153.7 | O9: 0.739 | P9: 7.429 | Q9: -153.7 | R9: -153.6 | S9: 0.739 | T9: 2.5184337 | U9: 83 | V9: 70 | W9: 16.772406 | X9: 0.42318469 | Y9: =SUM(C9:F9) -> 5.3
A10: 46121 | B10: 0 | C10: 0 | D10: 0 | E10: 3.5 | F10: 1 | G10: 1342.6 | H10: 1352.1 | I10: -9.5 | J10: -1 | K10: 0 | L10: 7.406 | M10: -153.8 | N10: -153.7 | O10: 0.724 | P10: 7.391 | Q10: -153.8 | R10: -153.6 | S10: 0.724 | T10: 2.5268848 | U10: 83 | V10: 70 | W10: 16.774872 | X10: 0.42323466 | Y10: =SUM(C10:F10) -> 4.5
A11: 46122 | B11: 0 | C11: 0 | D11: 0 | E11: 3.8 | F11: 0.8 | G11: 1338 | H11: 1346.9 | I11: -8.9 | J11: -1 | K11: 0 | L11: 7.363 | M11: -153.8 | N11: -153.7 | O11: 0.731 | P11: 7.368 | Q11: -153.8 | R11: -153.6 | S11: 0.732 | T11: 2.5358139 | U11: 83 | V11: 70 | W11: 16.777451 | X11: 0.4232866 | Y11: =SUM(C11:F11) -> 4.6
A12: 46123 | B12: 0 | C12: 0 | D12: 0 | E12: 3.3 | F12: 0.7 | G12: 1334 | H12: 1344.1 | I12: -10.1 | J12: -1 | K12: 0 | L12: 7.347 | M12: -153.8 | N12: -153.7 | O12: 0.731 | P12: 7.348 | Q12: -153.8 | R12: -153.6 | S12: 0.73 | T12: 2.5437029 | U12: 83 | V12: 70 | W12: 16.779607 | X12: 0.42333063 | Y12: =SUM(C12:F12) -> 4
A13: 46124 | B13: 0 | C13: 0 | D13: 0 | E13: 3.5 | F13: 0.9 | G13: 1329.6 | H13: 1341.7 | I13: -12.1 | J13: -1 | K13: 0 | L13: 7.333 | M13: -153.7 | N13: -153.7 | O13: 0.734 | P13: 7.331 | Q13: -153.7 | R13: -153.6 | S13: 0.734 | T13: 2.5525009 | U13: 83 | V13: 70 | W13: 16.78203 | X13: 0.42337998 | Y13: =SUM(C13:F13) -> 4.4
... A47: 46158 | B47: 0 | C47: 0 | D47: 0 | E47: 6.8 | F47: 0 | G47: 1020.4 | H47: 1043.8 | I47: -23.4 | J47: -1 | K47: 0 | L47: 5.712 | M47: -138.4 | N47: -152.5 | O47: 0.845 | P47: 5.851 | Q47: -139.4 | R47: -152.4 | S47: 0.844 | T47: 3.0129297 | U47: 81 | V47: 70 | W47: 16.911272 | X47: 0.42360927 | Y47: =SUM(C47:F47) -> 6.8

Sheet topaz_an
M1: 38 | N1: Date | O1: BDN | P1: ME_cons | Q1: F.vap_cons | R1: GE_cons | S1: BLR_cons | T1: ROB_cal | U1: ROB_cams | V1: Discrepancy | W1: Trim | X1: List | Y1: Level_TK1 | Z1: Vap_temp_TK1 | AA1: Liq_temp_TK1 | AB1: Press_TK1 | AC1: Level_TK2 | AD1: Vap_temp_TK2 | AE1: Liq_temp_TK2 | AF1: Press_TK2 | AG1: PKI | AH1: MN | AI1: Min_MN | AJ1: Molar_Mass | AK1: Density | AL1: CONSUMPTION
N2: {=INDEX(topaz!A:A,$M$1+ROW(A2))} -> 46151 | O2: {=INDEX(topaz!B:B,$M$1+ROW(B2))} -> 0 | P2: {=INDEX(topaz!C:C,$M$1+ROW(C2))} -> 0 | Q2: {=INDEX(topaz!D:D,$M$1+ROW(D2))} -> 0 | R2: {=INDEX(topaz!E:E,$M$1+ROW(E2))} -> 5.1 | S2: {=INDEX(topaz!F:F,$M$1+ROW(F2))} -> 0 | T2: {=INDEX(topaz!G:G,$M$1+ROW(G2))} -> 1055.6 | U2: {=INDEX(topaz!H:H,$M$1+ROW(H2))} -> 1068.3 | V2: {=INDEX(topaz!I:I,$M$1+ROW(I2))} -> -12.7 | W2: {=INDEX(topaz!J:J,$M$1+ROW(J2))} -> -1 | X2: {=INDEX(topaz!K:K,$M$1+ROW(K2))} -> 0 | Y2: {=INDEX(topaz!L:L,$M$1+ROW(L2))} -> 5.847 | Z2: {=INDEX(topaz!M:M,$M$1+ROW(M2))} -> -150.6 | AA2: {=INDEX(topaz!N:N,$M$1+ROW(N2))} -> -151.9 | AB2: {=INDEX(topaz!O:O,$M$1+ROW(O2))} -> 0.935 | AC2: {=INDEX(topaz!P:P,$M$1+ROW(P2))} -> 5.985 | AD2: {=INDEX(topaz!Q:Q,$M$1+ROW(Q2))} -> -150.9 | AE2: {=INDEX(topaz!R:R,$M$1+ROW(R2))} -> -151.8 | AF2: {=INDEX(topaz!S:S,$M$1+ROW(S2))} -> 0.935 | AG2: {=INDEX(topaz!T:T,$M$1+ROW(T2))} -> 2.9092224 | AH2: {=INDEX(topaz!U:U,$M$1+ROW(U2))} -> 81 | AI2: {=INDEX(topaz!V:V,$M$1+ROW(V2))} -> 70 | AJ2: {=INDEX(topaz!W:W,$M$1+ROW(W2))} -> 16.882303 | AK2: {=INDEX(topaz!X:X,$M$1+ROW(X2))} -> 0.42183877 | AL2: {=INDEX(topaz!Y:Y,$M$1+ROW(Y2))} -> 5.1
N3: {=INDEX(topaz!A:A,$M$1+ROW(A3))} -> 46152 | O3: {=INDEX(topaz!B:B,$M$1+ROW(B3))} -> 0 | P3: {=INDEX(topaz!C:C,$M$1+ROW(C3))} -> 0 | Q3: {=INDEX(topaz!D:D,$M$1+ROW(D3))} -> 0 | R3: {=INDEX(topaz!E:E,$M$1+ROW(E3))} -> 4.4 | S3: {=INDEX(topaz!F:F,$M$1+ROW(F3))} -> 0 | T3: {=INDEX(topaz!G:G,$M$1+ROW(G3))} -> 1051.2 | U3: {=INDEX(topaz!H:H,$M$1+ROW(H3))} -> 1065 | V3: {=INDEX(topaz!I:I,$M$1+ROW(I3))} -> -13.8 | W3: {=INDEX(topaz!J:J,$M$1+ROW(J3))} -> -1 | X3: {=INDEX(topaz!K:K,$M$1+ROW(K3))} -> 0 | Y3: {=INDEX(topaz!L:L,$M$1+ROW(L3))} -> 5.83 | Z3: {=INDEX(topaz!M:M,$M$1+ROW(M3))} -> -150.4 | AA3: {=INDEX(topaz!N:N,$M$1+ROW(N3))} -> -151.9 | AB3: {=INDEX(topaz!O:O,$M$1+ROW(O3))} -> 0.937 | AC3: {=INDEX(topaz!P:P,$M$1+ROW(P3))} -> 5.969 | AD3: {=INDEX(topaz!Q:Q,$M$1+ROW(Q3))} -> -150.8 | AE3: {=INDEX(topaz!R:R,$M$1+ROW(R3))} -> -151.8 | AF3: {=INDEX(topaz!S:S,$M$1+ROW(S3))} -> 0.936 | AG3: {=INDEX(topaz!T:T,$M$1+ROW(T3))} -> 2.9217077 | AH3: {=INDEX(topaz!U:U,$M$1+ROW(U3))} -> 81 | AI3: {=INDEX(topaz!V:V,$M$1+ROW(V3))} -> 70 | AJ3: {=INDEX(topaz!W:W,$M$1+ROW(W3))} -> 16.885834 | AK3: {=INDEX(topaz!X:X,$M$1+ROW(X3))} -> 0.42191013 | AL3: {=INDEX(topaz!Y:Y,$M$1+ROW(Y3))} -> 4.4
N4: {=INDEX(topaz!A:A,$M$1+ROW(A4))} -> 46153 | O4: {=INDEX(topaz!B:B,$M$1+ROW(B4))} -> 0 | P4: {=INDEX(topaz!C:C,$M$1+ROW(C4))} -> 0 | Q4: {=INDEX(topaz!D:D,$M$1+ROW(D4))} -> 0 | R4: {=INDEX(topaz!E:E,$M$1+ROW(E4))} -> 4.1 | S4: {=INDEX(topaz!F:F,$M$1+ROW(F4))} -> 0.1 | T4: {=INDEX(topaz!G:G,$M$1+ROW(G4))} -> 1047 | U4: {=INDEX(topaz!H:H,$M$1+ROW(H4))} -> 1060 | V4: {=INDEX(topaz!I:I,$M$1+ROW(I4))} -> -13 | W4: {=INDEX(topaz!J:J,$M$1+ROW(J4))} -> -1 | X4: {=INDEX(topaz!K:K,$M$1+ROW(K4))} -> 0 | Y4: {=INDEX(topaz!L:L,$M$1+ROW(L4))} -> 5.805 | Z4: {=INDEX(topaz!M:M,$M$1+ROW(M4))} -> -149.8 | AA4: {=INDEX(topaz!N:N,$M$1+ROW(N4))} -> -151.9 | AB4: {=INDEX(topaz!O:O,$M$1+ROW(O4))} -> 0.933 | AC4: {=INDEX(topaz!P:P,$M$1+ROW(P4))} -> 5.945 | AD4: {=INDEX(topaz!Q:Q,$M$1+ROW(Q4))} -> -150.4 | AE4: {=INDEX(topaz!R:R,$M$1+ROW(R4))} -> -151.8 | AF4: {=INDEX(topaz!S:S,$M$1+ROW(S4))} -> 0.932 | AG4: {=INDEX(topaz!T:T,$M$1+ROW(T4))} -> 2.9340513 | AH4: {=INDEX(topaz!U:U,$M$1+ROW(U4))} -> 81 | AI4: {=INDEX(topaz!V:V,$M$1+ROW(V4))} -> 70 | AJ4: {=INDEX(topaz!W:W,$M$1+ROW(W4))} -> 16.88918 | AK4: {=INDEX(topaz!X:X,$M$1+ROW(X4))} -> 0.42197811 | AL4: {=INDEX(topaz!Y:Y,$M$1+ROW(Y4))} -> 4.2
N5: {=INDEX(topaz!A:A,$M$1+ROW(A5))} -> 46154 | O5: {=INDEX(topaz!B:B,$M$1+ROW(B5))} -> 0 | P5: {=INDEX(topaz!C:C,$M$1+ROW(C5))} -> 0 | Q5: {=INDEX(topaz!D:D,$M$1+ROW(D5))} -> 0 | R5: {=INDEX(topaz!E:E,$M$1+ROW(E5))} -> 5 | S5: {=INDEX(topaz!F:F,$M$1+ROW(F5))} -> 0.1 | T5: {=INDEX(topaz!G:G,$M$1+ROW(G5))} -> 1041.9 | U5: {=INDEX(topaz!H:H,$M$1+ROW(H5))} -> 1054.7 | V5: {=INDEX(topaz!I:I,$M$1+ROW(I5))} -> -12.8 | W5: {=INDEX(topaz!J:J,$M$1+ROW(J5))} -> -1 | X5: {=INDEX(topaz!K:K,$M$1+ROW(K5))} -> 0 | Y5: {=INDEX(topaz!L:L,$M$1+ROW(L5))} -> 5.776 | Z5: {=INDEX(topaz!M:M,$M$1+ROW(M5))} -> -150.2 | AA5: {=INDEX(topaz!N:N,$M$1+ROW(N5))} -> -151.9 | AB5: {=INDEX(topaz!O:O,$M$1+ROW(O5))} -> 0.921 | AC5: {=INDEX(topaz!P:P,$M$1+ROW(P5))} -> 5.919 | AD5: {=INDEX(topaz!Q:Q,$M$1+ROW(Q5))} -> -150.7 | AE5: {=INDEX(topaz!R:R,$M$1+ROW(R5))} -> -151.9 | AF5: {=INDEX(topaz!S:S,$M$1+ROW(S5))} -> 0.919 | AG5: {=INDEX(topaz!T:T,$M$1+ROW(T5))} -> 2.9487446 | AH5: {=INDEX(topaz!U:U,$M$1+ROW(U5))} -> 81 | AI5: {=INDEX(topaz!V:V,$M$1+ROW(V5))} -> 70 | AJ5: {=INDEX(topaz!W:W,$M$1+ROW(W5))} -> 16.89337 | AK5: {=INDEX(topaz!X:X,$M$1+ROW(X5))} -> 0.42216244 | AL5: {=INDEX(topaz!Y:Y,$M$1+ROW(Y5))} -> 5.1
N6: {=INDEX(topaz!A:A,$M$1+ROW(A6))} -> 46155 | O6: {=INDEX(topaz!B:B,$M$1+ROW(B6))} -> 0 | P6: {=INDEX(topaz!C:C,$M$1+ROW(C6))} -> 0 | Q6: {=INDEX(topaz!D:D,$M$1+ROW(D6))} -> 0 | R6: {=INDEX(topaz!E:E,$M$1+ROW(E6))} -> 3.6 | S6: {=INDEX(topaz!F:F,$M$1+ROW(F6))} -> 0.6 | T6: {=INDEX(topaz!G:G,$M$1+ROW(G6))} -> 1037.7 | U6: {=INDEX(topaz!H:H,$M$1+ROW(H6))} -> 1053.3 | V6: {=INDEX(topaz!I:I,$M$1+ROW(I6))} -> -15.6 | W6: {=INDEX(topaz!J:J,$M$1+ROW(J6))} -> -1 | X6: {=INDEX(topaz!K:K,$M$1+ROW(K6))} -> 0 | Y6: {=INDEX(topaz!L:L,$M$1+ROW(L6))} -> 5.766 | Z6: {=INDEX(topaz!M:M,$M$1+ROW(M6))} -> -149.6 | AA6: {=INDEX(topaz!N:N,$M$1+ROW(N6))} -> -152 | AB6: {=INDEX(topaz!O:O,$M$1+ROW(O6))} -> 0.921 | AC6: {=INDEX(topaz!P:P,$M$1+ROW(P6))} -> 5.912 | AD6: {=INDEX(topaz!Q:Q,$M$1+ROW(Q6))} -> -150.5 | AE6: {=INDEX(topaz!R:R,$M$1+ROW(R6))} -> -151.9 | AF6: {=INDEX(topaz!S:S,$M$1+ROW(S6))} -> 0.92 | AG6: {=INDEX(topaz!T:T,$M$1+ROW(T6))} -> 2.9612621 | AH6: {=INDEX(topaz!U:U,$M$1+ROW(U6))} -> 81 | AI6: {=INDEX(topaz!V:V,$M$1+ROW(V6))} -> 70 | AJ6: {=INDEX(topaz!W:W,$M$1+ROW(W6))} -> 16.896772 | AK6: {=INDEX(topaz!X:X,$M$1+ROW(X6))} -> 0.42232859 | AL6: {=INDEX(topaz!Y:Y,$M$1+ROW(Y6))} -> 4.2
N7: {=INDEX(topaz!A:A,$M$1+ROW(A7))} -> 46156 | O7: {=INDEX(topaz!B:B,$M$1+ROW(B7))} -> 0 | P7: {=INDEX(topaz!C:C,$M$1+ROW(C7))} -> 0 | Q7: {=INDEX(topaz!D:D,$M$1+ROW(D7))} -> 0 | R7: {=INDEX(topaz!E:E,$M$1+ROW(E7))} -> 3.8 | S7: {=INDEX(topaz!F:F,$M$1+ROW(F7))} -> 0.6 | T7: {=INDEX(topaz!G:G,$M$1+ROW(G7))} -> 1033.3 | U7: {=INDEX(topaz!H:H,$M$1+ROW(H7))} -> 1048.5 | V7: {=INDEX(topaz!I:I,$M$1+ROW(I7))} -> -15.2 | W7: {=INDEX(topaz!J:J,$M$1+ROW(J7))} -> -1 | X7: {=INDEX(topaz!K:K,$M$1+ROW(K7))} -> 0 | Y7: {=INDEX(topaz!L:L,$M$1+ROW(L7))} -> 5.749 | Z7: {=INDEX(topaz!M:M,$M$1+ROW(M7))} -> -148.1 | AA7: {=INDEX(topaz!N:N,$M$1+ROW(N7))} -> -152 | AB7: {=INDEX(topaz!O:O,$M$1+ROW(O7))} -> 0.906 | AC7: {=INDEX(topaz!P:P,$M$1+ROW(P7))} -> 5.88 | AD7: {=INDEX(topaz!Q:Q,$M$1+ROW(Q7))} -> -149.2 | AE7: {=INDEX(topaz!R:R,$M$1+ROW(R7))} -> -152 | AF7: {=INDEX(topaz!S:S,$M$1+ROW(S7))} -> 0.905 | AG7: {=INDEX(topaz!T:T,$M$1+ROW(T7))} -> 2.9742225 | AH7: {=INDEX(topaz!U:U,$M$1+ROW(U7))} -> 81 | AI7: {=INDEX(topaz!V:V,$M$1+ROW(V7))} -> 70 | AJ7: {=INDEX(topaz!W:W,$M$1+ROW(W7))} -> 16.900443 | AK7: {=INDEX(topaz!X:X,$M$1+ROW(X7))} -> 0.42250271 | AL7: {=INDEX(topaz!Y:Y,$M$1+ROW(Y7))} -> 4.4
N8: {=INDEX(topaz!A:A,$M$1+ROW(A8))} -> 46157 | O8: {=INDEX(topaz!B:B,$M$1+ROW(B8))} -> 0 | P8: {=INDEX(topaz!C:C,$M$1+ROW(C8))} -> 0 | Q8: {=INDEX(topaz!D:D,$M$1+ROW(D8))} -> 0 | R8: {=INDEX(topaz!E:E,$M$1+ROW(E8))} -> 4.7 | S8: {=INDEX(topaz!F:F,$M$1+ROW(F8))} -> 1.4 | T8: {=INDEX(topaz!G:G,$M$1+ROW(G8))} -> 1027.2 | U8: {=INDEX(topaz!H:H,$M$1+ROW(H8))} -> 1048 | V8: {=INDEX(topaz!I:I,$M$1+ROW(I8))} -> -20.8 | W8: {=INDEX(topaz!J:J,$M$1+ROW(J8))} -> -1 | X8: {=INDEX(topaz!K:K,$M$1+ROW(K8))} -> 0 | Y8: {=INDEX(topaz!L:L,$M$1+ROW(L8))} -> 5.736 | Z8: {=INDEX(topaz!M:M,$M$1+ROW(M8))} -> -141.6 | AA8: {=INDEX(topaz!N:N,$M$1+ROW(N8))} -> -152.3 | AB8: {=INDEX(topaz!O:O,$M$1+ROW(O8))} -> 0.87 | AC8: {=INDEX(topaz!P:P,$M$1+ROW(P8))} -> 5.877 | AD8: {=INDEX(topaz!Q:Q,$M$1+ROW(Q8))} -> -142.5 | AE8: {=INDEX(topaz!R:R,$M$1+ROW(R8))} -> -152.2 | AF8: {=INDEX(topaz!S:S,$M$1+ROW(S8))} -> 0.868 | AG8: {=INDEX(topaz!T:T,$M$1+ROW(T8))} -> 2.9924777 | AH8: {=INDEX(topaz!U:U,$M$1+ROW(U8))} -> 81 | AI8: {=INDEX(topaz!V:V,$M$1+ROW(V8))} -> 70 | AJ8: {=INDEX(topaz!W:W,$M$1+ROW(W8))} -> 16.905471 | AK8: {=INDEX(topaz!X:X,$M$1+ROW(X8))} -> 0.42309667 | AL8: {=INDEX(topaz!Y:Y,$M$1+ROW(Y8))} -> 6.1
N9: {=INDEX(topaz!A:A,$M$1+ROW(A9))} -> 46158 | O9: {=INDEX(topaz!B:B,$M$1+ROW(B9))} -> 0 | P9: {=INDEX(topaz!C:C,$M$1+ROW(C9))} -> 0 | Q9: {=INDEX(topaz!D:D,$M$1+ROW(D9))} -> 0 | R9: {=INDEX(topaz!E:E,$M$1+ROW(E9))} -> 6.8 | S9: {=INDEX(topaz!F:F,$M$1+ROW(F9))} -> 0 | T9: {=INDEX(topaz!G:G,$M$1+ROW(G9))} -> 1020.4 | U9: {=INDEX(topaz!H:H,$M$1+ROW(H9))} -> 1043.8 | V9: {=INDEX(topaz!I:I,$M$1+ROW(I9))} -> -23.4 | W9: {=INDEX(topaz!J:J,$M$1+ROW(J9))} -> -1 | X9: {=INDEX(topaz!K:K,$M$1+ROW(K9))} -> 0 | Y9: {=INDEX(topaz!L:L,$M$1+ROW(L9))} -> 5.712 | Z9: {=INDEX(topaz!M:M,$M$1+ROW(M9))} -> -138.4 | AA9: {=INDEX(topaz!N:N,$M$1+ROW(N9))} -> -152.5 | AB9: {=INDEX(topaz!O:O,$M$1+ROW(O9))} -> 0.845 | AC9: {=INDEX(topaz!P:P,$M$1+ROW(P9))} -> 5.851 | AD9: {=INDEX(topaz!Q:Q,$M$1+ROW(Q9))} -> -139.4 | AE9: {=INDEX(topaz!R:R,$M$1+ROW(R9))} -> -152.4 | AF9: {=INDEX(topaz!S:S,$M$1+ROW(S9))} -> 0.844 | AG9: {=INDEX(topaz!T:T,$M$1+ROW(T9))} -> 3.0129297 | AH9: {=INDEX(topaz!U:U,$M$1+ROW(U9))} -> 81 | AI9: {=INDEX(topaz!V:V,$M$1+ROW(V9))} -> 70 | AJ9: {=INDEX(topaz!W:W,$M$1+ROW(W9))} -> 16.911272 | AK9: {=INDEX(topaz!X:X,$M$1+ROW(X9))} -> 0.42360927 | AL9: {=INDEX(topaz!Y:Y,$M$1+ROW(Y9))} -> 6.8

Sheet pearl
A1: Date | B1: BDN | C1: ME_cons | D1: F.vap_cons | E1: GE_cons | F1: BLR_cons | G1: ROB_cal | H1: ROB_cams | I1: Discrepancy | J1: Trim | K1: List | L1: Level_TK1 | M1: Vap_temp_TK1 | N1: Liq_temp_TK1 | O1: Press_TK1 | P1: Level_TK2 | Q1: Vap_temp_TK2 | R1: Liq_temp_TK2 | S1: Press_TK2 | T1: PKI | U1: MN | V1: Min_MN | W1: Molar_Mass | X1: Density | Y1: Consumptions
A2: 46113 | B2: 0 | C2: 0 | D2: 0 | E2: 5.3 | F2: 8.2 | G2: 1424 | H2: 1424 | I2: 0 | J2: -1 | K2: 0 | L2: 7.39 | M2: -153.2 | N2: -156.2 | O2: 0.52 | P2: 7.38 | Q2: -153.4 | R2: -155.6 | S2: 0.52 | T2: 4.551 | U2: 76 | V2: 70 | W2: 17.12 | X2: 0.42459267 | Y2: =SUM(C2:F2) -> 13.5
A3: 46114 | B3: 0 | C3: 0 | D3: 0 | E3: 4.3 | F3: 5.6 | G3: 1414.1 | H3: 1388.5 | I3: 25.6 | J3: -1 | K3: 0 | L3: 7.39 | M3: -153.2 | N3: -156.2 | O3: 0.52 | P3: 7.38 | Q3: -153.4 | R3: -155.6 | S3: 0.52 | T3: 4.5831324 | U3: 76 | V3: 70 | W3: 17.127546 | X3: 0.4354339 | Y3: =SUM(C3:F3) -> 9.9
A4: 46115 | B4: 0 | C4: 0 | D4: 0 | E4: 4.3 | F4: 0.9 | G4: 1408.9 | H4: 1380.3 | I4: 28.6 | J4: -1 | K4: 0 | L4: 7.38 | M4: -150.7 | N4: -155.8 | O4: 0.88 | P4: 7.32 | Q4: -149.9 | R4: -155.1 | S4: 0.88 | T4: 4.6004612 | U4: 76 | V4: 70 | W4: 17.131523 | X4: 0.43459958 | Y4: =SUM(C4:F4) -> 5.2
A5: 46116 | B5: 0 | C5: 0 | D5: 0 | E5: 5.2 | F5: 1.2 | G5: 1402.5 | H5: 1353.5 | I5: 49 | J5: -1 | K5: 0 | L5: 7.291 | M5: -145.7 | N5: -155.4 | O5: 1.01 | P5: 7.133 | Q5: -144.9 | R5: -154.4 | S5: 1.01 | T5: 4.6213771 | U5: 76 | V5: 70 | W5: 17.136481 | X5: 0.4336269 | Y5: =SUM(C5:F5) -> 6.4
A6: 46117 | B6: 0 | C6: 0 | D6: 0 | E6: 4.5 | F6: 1.1 | G6: 1396.9 | H6: 1351.5 | I6: 45.4 | J6: -1 | K6: 0 | L6: 7.299 | M6: -143.9 | N6: -155 | O6: 0.84 | P6: 7.14 | Q6: -144.3 | R6: -153.7 | S6: 0.84 | T6: 4.6400656 | U6: 76 | V6: 70 | W6: 17.140979 | X6: 0.43262162 | Y6: =SUM(C6:F6) -> 5.6
A7: 46118 | B7: 0 | C7: 0 | D7: 0 | E7: 4 | F7: 1.2 | G7: 1391.7 | H7: 1346.7 | I7: 45 | J7: -1 | K7: 0 | L7: 7.298 | M7: -149.6 | N7: -154.6 | O7: 0.71 | P7: 7.092 | Q7: -148.9 | R7: -153.9 | S7: 0.72 | T7: 4.6576219 | U7: 76 | V7: 70 | W7: 17.145041 | X7: 0.43252134 | Y7: =SUM(C7:F7) -> 5.2
A8: 46119 | B8: 0 | C8: 0 | D8: 0 | E8: 3.6 | F8: 1.1 | G8: 1387 | H8: 1342.8 | I8: 44.2 | J8: -1 | K8: 0 | L8: 7.288 | M8: -150.9 | N8: -154.4 | O8: 0.7 | P8: 7.055 | Q8: -149.4 | R8: -154.1 | S8: 0.7 | T8: 4.6739839 | U8: 76 | V8: 70 | W8: 17.148709 | X8: 0.43260269 | Y8: =SUM(C8:F8) -> 4.7
A9: 46120 | B9: 0 | C9: 0 | D9: 0 | E9: 3.8 | F9: 1.1 | G9: 1382.1 | H9: 1338 | I9: 44.1 | J9: -1 | K9: 0 | L9: 7.259 | M9: -150.8 | N9: -154.4 | O9: 0.69 | P9: 7.027 | Q9: -149.3 | R9: -154.1 | S9: 0.69 | T9: 4.6904886 | U9: 76 | V9: 70 | W9: 17.152691 | X9: 0.43268321 | Y9: =SUM(C9:F9) -> 4.9
A10: 46121 | B10: 0 | C10: 0 | D10: 0 | E10: 4.3 | F10: 0.95 | G10: 1376.8 | H10: 1336.8 | I10: 40 | J10: -1 | K10: 0 | L10: 7.208 | M10: -147.7 | N10: -154 | O10: 1.03 | P10: 7.076 | Q10: -143 | R10: -153.9 | S10: 1.03 | T10: 4.7085808 | U10: 75 | V10: 70 | W10: 17.156907 | X10: 0.43217286 | Y10: =SUM(C10:F10) -> 5.25
A11: 46122 | B11: 0 | C11: 0 | D11: 0 | E11: 3.8 | F11: 1.05 | G11: 1372 | H11: 1325 | I11: 47 | J11: -1 | K11: 0 | L11: 7.166 | M11: -146.8 | N11: -153.4 | O11: 0.88 | P11: 7.02 | Q11: -142.2 | R11: -153.5 | S11: 0.88 | T11: 4.7257076 | U11: 75 | V11: 70 | W11: 17.160814 | X11: 0.43125122 | Y11: =SUM(C11:F11) -> 4.85
A12: 46123 | B12: 0 | C12: 0 | D12: 0 | E12: 4.8 | F12: 0.05 | G12: 1367.2 | H12: 1319.9 | I12: 47.3 | J12: -1 | K12: 0 | L12: 7.131 | M12: -151.6 | N12: -153.3 | O12: 0.82 | P12: 7.008 | Q12: -150.7 | R12: -153.2 | S12: 0.82 | T12: 4.742705 | U12: 75 | V12: 70 | W12: 17.164807 | X12: 0.43093623 | Y12: =SUM(C12:F12) -> 4.85
A13: 46124 | B13: 0 | C13: 0 | D13: 0 | E13: 4.7 | F13: 0 | G13: 1362.4 | H13: 1316.3 | I13: 46.1 | J13: -1 | K13: 0 | L13: 7.111 | M13: -148.8 | N13: -153.3 | O13: 0.816 | P13: 6.989 | Q13: -147.1 | R13: -153.1 | S13: 0.819 | T13: 4.7588018 | U13: 75 | V13: 70 | W13: 17.168691 | X13: 0.43091717 | Y13: =SUM(C13:F13) -> 4.7
... A106: 46217 | B106: 0 | C106: 0 | D106: 0 | E106: 2 | F106: 0 | G106: 711.4 | H106: 719 | I106: -7.6 | J106: 0 | K106: 0 | L106: 4.162 | M106: -126.6 | N106: -147.3 | O106: 1.581 | P106: 4.165 | Q106: -125.9 | R106: -147 | S106: 1.586 | T106: 7.4511571 | U106: 70 | V106: 70 | W106: 17.802957 | X106: 0.43793787 | Y106: =SUM(C106:F106) -> 2

Sheet pearl_an
M1: 0 | N1: Date | O1: BDN | P1: ME_cons | Q1: F.vap_cons | R1: GE_cons | S1: BLR_cons | T1: ROB_cal | U1: ROB_cams | V1: Discrepancy | W1: Trim | X1: List | Y1: Level_TK1 | Z1: Vap_temp_TK1 | AA1: Liq_temp_TK1 | AB1: Press_TK1 | AC1: Level_TK2 | AD1: Vap_temp_TK2 | AE1: Liq_temp_TK2 | AF1: Press_TK2 | AG1: PKI | AH1: MN | AI1: Min_MN | AJ1: Molar_Mass | AK1: Density | AL1: CONSUMPTION
N2: {=INDEX(pearl!A:A,$M$1+ROW(A2))} -> 46113 | O2: {=INDEX(pearl!B:B,$M$1+ROW(B2))} -> 0 | P2: {=INDEX(pearl!C:C,$M$1+ROW(C2))} -> 0 | Q2: {=INDEX(pearl!D:D,$M$1+ROW(D2))} -> 0 | R2: {=INDEX(pearl!E:E,$M$1+ROW(E2))} -> 5.3 | S2: {=INDEX(pearl!F:F,$M$1+ROW(F2))} -> 8.2 | T2: {=INDEX(pearl!G:G,$M$1+ROW(G2))} -> 1424 | U2: {=INDEX(pearl!H:H,$M$1+ROW(H2))} -> 1424 | V2: {=INDEX(pearl!I:I,$M$1+ROW(I2))} -> 0 | W2: {=INDEX(pearl!J:J,$M$1+ROW(J2))} -> -1 | X2: {=INDEX(pearl!K:K,$M$1+ROW(K2))} -> 0 | Y2: {=INDEX(pearl!L:L,$M$1+ROW(L2))} -> 7.39 | Z2: {=INDEX(pearl!M:M,$M$1+ROW(M2))} -> -153.2 | AA2: {=INDEX(pearl!N:N,$M$1+ROW(N2))} -> -156.2 | AB2: {=INDEX(pearl!O:O,$M$1+ROW(O2))} -> 0.52 | AC2: {=INDEX(pearl!P:P,$M$1+ROW(P2))} -> 7.38 | AD2: {=INDEX(pearl!Q:Q,$M$1+ROW(Q2))} -> -153.4 | AE2: {=INDEX(pearl!R:R,$M$1+ROW(R2))} -> -155.6 | AF2: {=INDEX(pearl!S:S,$M$1+ROW(S2))} -> 0.52 | AG2: {=INDEX(pearl!T:T,$M$1+ROW(T2))} -> 4.551 | AH2: {=INDEX(pearl!U:U,$M$1+ROW(U2))} -> 76 | AI2: {=INDEX(pearl!V:V,$M$1+ROW(V2))} -> 70 | AJ2: {=INDEX(pearl!W:W,$M$1+ROW(W2))} -> 17.12 | AK2: {=INDEX(pearl!X:X,$M$1+ROW(X2))} -> 0.42459267 | AL2: {=INDEX(pearl!Y:Y,$M$1+ROW(Y2))} -> 13.5
N3: {=INDEX(pearl!A:A,$M$1+ROW(A3))} -> 46114 | O3: {=INDEX(pearl!B:B,$M$1+ROW(B3))} -> 0 | P3: {=INDEX(pearl!C:C,$M$1+ROW(C3))} -> 0 | Q3: {=INDEX(pearl!D:D,$M$1+ROW(D3))} -> 0 | R3: {=INDEX(pearl!E:E,$M$1+ROW(E3))} -> 4.3 | S3: {=INDEX(pearl!F:F,$M$1+ROW(F3))} -> 5.6 | T3: {=INDEX(pearl!G:G,$M$1+ROW(G3))} -> 1414.1 | U3: {=INDEX(pearl!H:H,$M$1+ROW(H3))} -> 1388.5 | V3: {=INDEX(pearl!I:I,$M$1+ROW(I3))} -> 25.6 | W3: {=INDEX(pearl!J:J,$M$1+ROW(J3))} -> -1 | X3: {=INDEX(pearl!K:K,$M$1+ROW(K3))} -> 0 | Y3: {=INDEX(pearl!L:L,$M$1+ROW(L3))} -> 7.39 | Z3: {=INDEX(pearl!M:M,$M$1+ROW(M3))} -> -153.2 | AA3: {=INDEX(pearl!N:N,$M$1+ROW(N3))} -> -156.2 | AB3: {=INDEX(pearl!O:O,$M$1+ROW(O3))} -> 0.52 | AC3: {=INDEX(pearl!P:P,$M$1+ROW(P3))} -> 7.38 | AD3: {=INDEX(pearl!Q:Q,$M$1+ROW(Q3))} -> -153.4 | AE3: {=INDEX(pearl!R:R,$M$1+ROW(R3))} -> -155.6 | AF3: {=INDEX(pearl!S:S,$M$1+ROW(S3))} -> 0.52 | AG3: {=INDEX(pearl!T:T,$M$1+ROW(T3))} -> 4.5831324 | AH3: {=INDEX(pearl!U:U,$M$1+ROW(U3))} -> 76 | AI3: {=INDEX(pearl!V:V,$M$1+ROW(V3))} -> 70 | AJ3: {=INDEX(pearl!W:W,$M$1+ROW(W3))} -> 17.127546 | AK3: {=INDEX(pearl!X:X,$M$1+ROW(X3))} -> 0.4354339 | AL3: {=INDEX(pearl!Y:Y,$M$1+ROW(Y3))} -> 9.9
N4: {=INDEX(pearl!A:A,$M$1+ROW(A4))} -> 46115 | O4: {=INDEX(pearl!B:B,$M$1+ROW(B4))} -> 0 | P4: {=INDEX(pearl!C:C,$M$1+ROW(C4))} -> 0 | Q4: {=INDEX(pearl!D:D,$M$1+ROW(D4))} -> 0 | R4: {=INDEX(pearl!E:E,$M$1+ROW(E4))} -> 4.3 | S4: {=INDEX(pearl!F:F,$M$1+ROW(F4))} -> 0.9 | T4: {=INDEX(pearl!G:G,$M$1+ROW(G4))} -> 1408.9 | U4: {=INDEX(pearl!H:H,$M$1+ROW(H4))} -> 1380.3 | V4: {=INDEX(pearl!I:I,$M$1+ROW(I4))} -> 28.6 | W4: {=INDEX(pearl!J:J,$M$1+ROW(J4))} -> -1 | X4: {=INDEX(pearl!K:K,$M$1+ROW(K4))} -> 0 | Y4: {=INDEX(pearl!L:L,$M$1+ROW(L4))} -> 7.38 | Z4: {=INDEX(pearl!M:M,$M$1+ROW(M4))} -> -150.7 | AA4: {=INDEX(pearl!N:N,$M$1+ROW(N4))} -> -155.8 | AB4: {=INDEX(pearl!O:O,$M$1+ROW(O4))} -> 0.88 | AC4: {=INDEX(pearl!P:P,$M$1+ROW(P4))} -> 7.32 | AD4: {=INDEX(pearl!Q:Q,$M$1+ROW(Q4))} -> -149.9 | AE4: {=INDEX(pearl!R:R,$M$1+ROW(R4))} -> -155.1 | AF4: {=INDEX(pearl!S:S,$M$1+ROW(S4))} -> 0.88 | AG4: {=INDEX(pearl!T:T,$M$1+ROW(T4))} -> 4.6004612 | AH4: {=INDEX(pearl!U:U,$M$1+ROW(U4))} -> 76 | AI4: {=INDEX(pearl!V:V,$M$1+ROW(V4))} -> 70 | AJ4: {=INDEX(pearl!W:W,$M$1+ROW(W4))} -> 17.131523 | AK4: {=INDEX(pearl!X:X,$M$1+ROW(X4))} -> 0.43459958 | AL4: {=INDEX(pearl!Y:Y,$M$1+ROW(Y4))} -> 5.2
N5: {=INDEX(pearl!A:A,$M$1+ROW(A5))} -> 46116 | O5: {=INDEX(pearl!B:B,$M$1+ROW(B5))} -> 0 | P5: {=INDEX(pearl!C:C,$M$1+ROW(C5))} -> 0 | Q5: {=INDEX(pearl!D:D,$M$1+ROW(D5))} -> 0 | R5: {=INDEX(pearl!E:E,$M$1+ROW(E5))} -> 5.2 | S5: {=INDEX(pearl!F:F,$M$1+ROW(F5))} -> 1.2 | T5: {=INDEX(pearl!G:G,$M$1+ROW(G5))} -> 1402.5 | U5: {=INDEX(pearl!H:H,$M$1+ROW(H5))} -> 1353.5 | V5: {=INDEX(pearl!I:I,$M$1+ROW(I5))} -> 49 | W5: {=INDEX(pearl!J:J,$M$1+ROW(J5))} -> -1 | X5: {=INDEX(pearl!K:K,$M$1+ROW(K5))} -> 0 | Y5: {=INDEX(pearl!L:L,$M$1+ROW(L5))} -> 7.291 | Z5: {=INDEX(pearl!M:M,$M$1+ROW(M5))} -> -145.7 | AA5: {=INDEX(pearl!N:N,$M$1+ROW(N5))} -> -155.4 | AB5: {=INDEX(pearl!O:O,$M$1+ROW(O5))} -> 1.01 | AC5: {=INDEX(pearl!P:P,$M$1+ROW(P5))} -> 7.133 | AD5: {=INDEX(pearl!Q:Q,$M$1+ROW(Q5))} -> -144.9 | AE5: {=INDEX(pearl!R:R,$M$1+ROW(R5))} -> -154.4 | AF5: {=INDEX(pearl!S:S,$M$1+ROW(S5))} -> 1.01 | AG5: {=INDEX(pearl!T:T,$M$1+ROW(T5))} -> 4.6213771 | AH5: {=INDEX(pearl!U:U,$M$1+ROW(U5))} -> 76 | AI5: {=INDEX(pearl!V:V,$M$1+ROW(V5))} -> 70 | AJ5: {=INDEX(pearl!W:W,$M$1+ROW(W5))} -> 17.136481 | AK5: {=INDEX(pearl!X:X,$M$1+ROW(X5))} -> 0.4336269 | AL5: {=INDEX(pearl!Y:Y,$M$1+ROW(Y5))} -> 6.4
N6: {=INDEX(pearl!A:A,$M$1+ROW(A6))} -> 46117 | O6: {=INDEX(pearl!B:B,$M$1+ROW(B6))} -> 0 | P6: {=INDEX(pearl!C:C,$M$1+ROW(C6))} -> 0 | Q6: {=INDEX(pearl!D:D,$M$1+ROW(D6))} -> 0 | R6: {=INDEX(pearl!E:E,$M$1+ROW(E6))} -> 4.5 | S6: {=INDEX(pearl!F:F,$M$1+ROW(F6))} -> 1.1 | T6: {=INDEX(pearl!G:G,$M$1+ROW(G6))} -> 1396.9 | U6: {=INDEX(pearl!H:H,$M$1+ROW(H6))} -> 1351.5 | V6: {=INDEX(pearl!I:I,$M$1+ROW(I6))} -> 45.4 | W6: {=INDEX(pearl!J:J,$M$1+ROW(J6))} -> -1 | X6: {=INDEX(pearl!K:K,$M$1+ROW(K6))} -> 0 | Y6: {=INDEX(pearl!L:L,$M$1+ROW(L6))} -> 7.299 | Z6: {=INDEX(pearl!M:M,$M$1+ROW(M6))} -> -143.9 | AA6: {=INDEX(pearl!N:N,$M$1+ROW(N6))} -> -155 | AB6: {=INDEX(pearl!O:O,$M$1+ROW(O6))} -> 0.84 | AC6: {=INDEX(pearl!P:P,$M$1+ROW(P6))} -> 7.14 | AD6: {=INDEX(pearl!Q:Q,$M$1+ROW(Q6))} -> -144.3 | AE6: {=INDEX(pearl!R:R,$M$1+ROW(R6))} -> -153.7 | AF6: {=INDEX(pearl!S:S,$M$1+ROW(S6))} -> 0.84 | AG6: {=INDEX(pearl!T:T,$M$1+ROW(T6))} -> 4.6400656 | AH6: {=INDEX(pearl!U:U,$M$1+ROW(U6))} -> 76 | AI6: {=INDEX(pearl!V:V,$M$1+ROW(V6))} -> 70 | AJ6: {=INDEX(pearl!W:W,$M$1+ROW(W6))} -> 17.140979 | AK6: {=INDEX(pearl!X:X,$M$1+ROW(X6))} -> 0.43262162 | AL6: {=INDEX(pearl!Y:Y,$M$1+ROW(Y6))} -> 5.6
N7: {=INDEX(pearl!A:A,$M$1+ROW(A7))} -> 46118 | O7: {=INDEX(pearl!B:B,$M$1+ROW(B7))} -> 0 | P7: {=INDEX(pearl!C:C,$M$1+ROW(C7))} -> 0 | Q7: {=INDEX(pearl!D:D,$M$1+ROW(D7))} -> 0 | R7: {=INDEX(pearl!E:E,$M$1+ROW(E7))} -> 4 | S7: {=INDEX(pearl!F:F,$M$1+ROW(F7))} -> 1.2 | T7: {=INDEX(pearl!G:G,$M$1+ROW(G7))} -> 1391.7 | U7: {=INDEX(pearl!H:H,$M$1+ROW(H7))} -> 1346.7 | V7: {=INDEX(pearl!I:I,$M$1+ROW(I7))} -> 45 | W7: {=INDEX(pearl!J:J,$M$1+ROW(J7))} -> -1 | X7: {=INDEX(pearl!K:K,$M$1+ROW(K7))} -> 0 | Y7: {=INDEX(pearl!L:L,$M$1+ROW(L7))} -> 7.298 | Z7: {=INDEX(pearl!M:M,$M$1+ROW(M7))} -> -149.6 | AA7: {=INDEX(pearl!N:N,$M$1+ROW(N7))} -> -154.6 | AB7: {=INDEX(pearl!O:O,$M$1+ROW(O7))} -> 0.71 | AC7: {=INDEX(pearl!P:P,$M$1+ROW(P7))} -> 7.092 | AD7: {=INDEX(pearl!Q:Q,$M$1+ROW(Q7))} -> -148.9 | AE7: {=INDEX(pearl!R:R,$M$1+ROW(R7))} -> -153.9 | AF7: {=INDEX(pearl!S:S,$M$1+ROW(S7))} -> 0.72 | AG7: {=INDEX(pearl!T:T,$M$1+ROW(T7))} -> 4.6576219 | AH7: {=INDEX(pearl!U:U,$M$1+ROW(U7))} -> 76 | AI7: {=INDEX(pearl!V:V,$M$1+ROW(V7))} -> 70 | AJ7: {=INDEX(pearl!W:W,$M$1+ROW(W7))} -> 17.145041 | AK7: {=INDEX(pearl!X:X,$M$1+ROW(X7))} -> 0.43252134 | AL7: {=INDEX(pearl!Y:Y,$M$1+ROW(Y7))} -> 5.2
N8: {=INDEX(pearl!A:A,$M$1+ROW(A8))} -> 46119 | O8: {=INDEX(pearl!B:B,$M$1+ROW(B8))} -> 0 | P8: {=INDEX(pearl!C:C,$M$1+ROW(C8))} -> 0 | Q8: {=INDEX(pearl!D:D,$M$1+ROW(D8))} -> 0 | R8: {=INDEX(pearl!E:E,$M$1+ROW(E8))} -> 3.6 | S8: {=INDEX(pearl!F:F,$M$1+ROW(F8))} -> 1.1 | T8: {=INDEX(pearl!G:G,$M$1+ROW(G8))} -> 1387 | U8: {=INDEX(pearl!H:H,$M$1+ROW(H8))} -> 1342.8 | V8: {=INDEX(pearl!I:I,$M$1+ROW(I8))} -> 44.2 | W8: {=INDEX(pearl!J:J,$M$1+ROW(J8))} -> -1 | X8: {=INDEX(pearl!K:K,$M$1+ROW(K8))} -> 0 | Y8: {=INDEX(pearl!L:L,$M$1+ROW(L8))} -> 7.288 | Z8: {=INDEX(pearl!M:M,$M$1+ROW(M8))} -> -150.9 | AA8: {=INDEX(pearl!N:N,$M$1+ROW(N8))} -> -154.4 | AB8: {=INDEX(pearl!O:O,$M$1+ROW(O8))} -> 0.7 | AC8: {=INDEX(pearl!P:P,$M$1+ROW(P8))} -> 7.055 | AD8: {=INDEX(pearl!Q:Q,$M$1+ROW(Q8))} -> -149.4 | AE8: {=INDEX(pearl!R:R,$M$1+ROW(R8))} -> -154.1 | AF8: {=INDEX(pearl!S:S,$M$1+ROW(S8))} -> 0.7 | AG8: {=INDEX(pearl!T:T,$M$1+ROW(T8))} -> 4.6739839 | AH8: {=INDEX(pearl!U:U,$M$1+ROW(U8))} -> 76 | AI8: {=INDEX(pearl!V:V,$M$1+ROW(V8))} -> 70 | AJ8: {=INDEX(pearl!W:W,$M$1+ROW(W8))} -> 17.148709 | AK8: {=INDEX(pearl!X:X,$M$1+ROW(X8))} -> 0.43260269 | AL8: {=INDEX(pearl!Y:Y,$M$1+ROW(Y8))} -> 4.7
N9: {=INDEX(pearl!A:A,$M$1+ROW(A9))} -> 46120 | O9: {=INDEX(pearl!B:B,$M$1+ROW(B9))} -> 0 | P9: {=INDEX(pearl!C:C,$M$1+ROW(C9))} -> 0 | Q9: {=INDEX(pearl!D:D,$M$1+ROW(D9))} -> 0 | R9: {=INDEX(pearl!E:E,$M$1+ROW(E9))} -> 3.8 | S9: {=INDEX(pearl!F:F,$M$1+ROW(F9))} -> 1.1 | T9: {=INDEX(pearl!G:G,$M$1+ROW(G9))} -> 1382.1 | U9: {=INDEX(pearl!H:H,$M$1+ROW(H9))} -> 1338 | V9: {=INDEX(pearl!I:I,$M$1+ROW(I9))} -> 44.1 | W9: {=INDEX(pearl!J:J,$M$1+ROW(J9))} -> -1 | X9: {=INDEX(pearl!K:K,$M$1+ROW(K9))} -> 0 | Y9: {=INDEX(pearl!L:L,$M$1+ROW(L9))} -> 7.259 | Z9: {=INDEX(pearl!M:M,$M$1+ROW(M9))} -> -150.8 | AA9: {=INDEX(pearl!N:N,$M$1+ROW(N9))} -> -154.4 | AB9: {=INDEX(pearl!O:O,$M$1+ROW(O9))} -> 0.69 | AC9: {=INDEX(pearl!P:P,$M$1+ROW(P9))} -> 7.027 | AD9: {=INDEX(pearl!Q:Q,$M$1+ROW(Q9))} -> -149.3 | AE9: {=INDEX(pearl!R:R,$M$1+ROW(R9))} -> -154.1 | AF9: {=INDEX(pearl!S:S,$M$1+ROW(S9))} -> 0.69 | AG9: {=INDEX(pearl!T:T,$M$1+ROW(T9))} -> 4.6904886 | AH9: {=INDEX(pearl!U:U,$M$1+ROW(U9))} -> 76 | AI9: {=INDEX(pearl!V:V,$M$1+ROW(V9))} -> 70 | AJ9: {=INDEX(pearl!W:W,$M$1+ROW(W9))} -> 17.152691 | AK9: {=INDEX(pearl!X:X,$M$1+ROW(X9))} -> 0.43268321 | AL9: {=INDEX(pearl!Y:Y,$M$1+ROW(Y9))} -> 4.9

Sheet normalise
K1: 14 | L1: Date | M1: Discrepancy | N1: Date | O1: Discrepancy | P1: Date | Q1: Discrepancy | S1: Date_Amber | T1: Norm_Amber | U1: Date_Topaz | V1: Norm_Topaz | W1: Date_Pearl | X1: Norm_Pearl
L2: {=INDEX(amber!A:A,$K$1+ROW(A2))} -> 46127 | M2: {=INDEX(amber!I:I,$K$1+ROW(I2))} -> -19.3 | N2: {=INDEX(topaz!A:A,$K$1+ROW(A2))} -> 46127 | O2: {=INDEX(topaz!I:I,$K$1+ROW(I2))} -> -10.3 | P2: {=INDEX(pearl!A:A,$K$1+ROW(A2))} -> 46127 | Q2: {=INDEX(pearl!I:I,$K$1+ROW(I2))} -> 42.2 | S2: {=INDEX($L$2:$L$21,$K$1+ROW()-1)} -> 46141 | T2: {=INDEX($M$2:$M$21,$K$1+ROW()-1)-INDEX($M$2:$M$21,$K$1+1)} -> 0 | U2: {=INDEX($N$2:$N$21,$K$1+ROW()-1)} -> 46141 | V2: {=INDEX($O$2:$O$21,$K$1+ROW()-1)-INDEX($O$2:$O$21,$K$1+1)} -> 0 | W2: {=INDEX($P$2:$P$21,$K$1+ROW()-1)} -> 46141 | X2: {=INDEX($Q$2:$Q$21,$K$1+ROW()-1)-INDEX($Q$2:$Q$21,$K$1+1)} -> 0
L3: {=INDEX(amber!A:A,$K$1+ROW(A3))} -> 46128 | M3: {=INDEX(amber!I:I,$K$1+ROW(I3))} -> -17.7 | N3: {=INDEX(topaz!A:A,$K$1+ROW(A3))} -> 46128 | O3: {=INDEX(topaz!I:I,$K$1+ROW(I3))} -> -12.3 | P3: {=INDEX(pearl!A:A,$K$1+ROW(A3))} -> 46128 | Q3: {=INDEX(pearl!I:I,$K$1+ROW(I3))} -> 42.6 | S3: {=INDEX($L$2:$L$21,$K$1+ROW()-1)} -> 46142 | T3: {=INDEX($M$2:$M$21,$K$1+ROW()-1)-INDEX($M$2:$M$21,$K$1+1)} -> 0.6 | U3: {=INDEX($N$2:$N$21,$K$1+ROW()-1)} -> 46142 | V3: {=INDEX($O$2:$O$21,$K$1+ROW()-1)-INDEX($O$2:$O$21,$K$1+1)} -> 2.5 | W3: {=INDEX($P$2:$P$21,$K$1+ROW()-1)} -> 46142 | X3: {=INDEX($Q$2:$Q$21,$K$1+ROW()-1)-INDEX($Q$2:$Q$21,$K$1+1)} -> -2
L4: {=INDEX(amber!A:A,$K$1+ROW(A4))} -> 46129 | M4: {=INDEX(amber!I:I,$K$1+ROW(I4))} -> -20.9 | N4: {=INDEX(topaz!A:A,$K$1+ROW(A4))} -> 46129 | O4: {=INDEX(topaz!I:I,$K$1+ROW(I4))} -> -12 | P4: {=INDEX(pearl!A:A,$K$1+ROW(A4))} -> 46129 | Q4: {=INDEX(pearl!I:I,$K$1+ROW(I4))} -> 40.9 | S4: {=INDEX($L$2:$L$21,$K$1+ROW()-1)} -> 46143 | T4: {=INDEX($M$2:$M$21,$K$1+ROW()-1)-INDEX($M$2:$M$21,$K$1+1)} -> -0.6 | U4: {=INDEX($N$2:$N$21,$K$1+ROW()-1)} -> 46143 | V4: {=INDEX($O$2:$O$21,$K$1+ROW()-1)-INDEX($O$2:$O$21,$K$1+1)} -> 5 | W4: {=INDEX($P$2:$P$21,$K$1+ROW()-1)} -> 46143 | X4: {=INDEX($Q$2:$Q$21,$K$1+ROW()-1)-INDEX($Q$2:$Q$21,$K$1+1)} -> 0.6
L5: {=INDEX(amber!A:A,$K$1+ROW(A5))} -> 46130 | M5: {=INDEX(amber!I:I,$K$1+ROW(I5))} -> -22.8 | N5: {=INDEX(topaz!A:A,$K$1+ROW(A5))} -> 46130 | O5: {=INDEX(topaz!I:I,$K$1+ROW(I5))} -> -11.4 | P5: {=INDEX(pearl!A:A,$K$1+ROW(A5))} -> 46130 | Q5: {=INDEX(pearl!I:I,$K$1+ROW(I5))} -> 40.4
L6: {=INDEX(amber!A:A,$K$1+ROW(A6))} -> 46131 | M6: {=INDEX(amber!I:I,$K$1+ROW(I6))} -> -18.5 | N6: {=INDEX(topaz!A:A,$K$1+ROW(A6))} -> 46131 | O6: {=INDEX(topaz!I:I,$K$1+ROW(I6))} -> -13.6 | P6: {=INDEX(pearl!A:A,$K$1+ROW(A6))} -> 46131 | Q6: {=INDEX(pearl!I:I,$K$1+ROW(I6))} -> 38.3
L7: {=INDEX(amber!A:A,$K$1+ROW(A7))} -> 46132 | M7: {=INDEX(amber!I:I,$K$1+ROW(I7))} -> 1.9 | N7: {=INDEX(topaz!A:A,$K$1+ROW(A7))} -> 46132 | O7: {=INDEX(topaz!I:I,$K$1+ROW(I7))} -> -14.1 | P7: {=INDEX(pearl!A:A,$K$1+ROW(A7))} -> 46132 | Q7: {=INDEX(pearl!I:I,$K$1+ROW(I7))} -> 42.9
L8: {=INDEX(amber!A:A,$K$1+ROW(A8))} -> 46133 | M8: {=INDEX(amber!I:I,$K$1+ROW(I8))} -> 3 | N8: {=INDEX(topaz!A:A,$K$1+ROW(A8))} -> 46133 | O8: {=INDEX(topaz!I:I,$K$1+ROW(I8))} -> -20.3 | P8: {=INDEX(pearl!A:A,$K$1+ROW(A8))} -> 46133 | Q8: {=INDEX(pearl!I:I,$K$1+ROW(I8))} -> 39.4
L9: {=INDEX(amber!A:A,$K$1+ROW(A9))} -> 46134 | M9: {=INDEX(amber!I:I,$K$1+ROW(I9))} -> 2.4 | N9: {=INDEX(topaz!A:A,$K$1+ROW(A9))} -> 46134 | O9: {=INDEX(topaz!I:I,$K$1+ROW(I9))} -> -22.4 | P9: {=INDEX(pearl!A:A,$K$1+ROW(A9))} -> 46134 | Q9: {=INDEX(pearl!I:I,$K$1+ROW(I9))} -> 35.3
L10: {=INDEX(amber!A:A,$K$1+ROW(A10))} -> 46135 | M10: {=INDEX(amber!I:I,$K$1+ROW(I10))} -> -0.2 | N10: {=INDEX(topaz!A:A,$K$1+ROW(A10))} -> 46135 | O10: {=INDEX(topaz!I:I,$K$1+ROW(I10))} -> -21.8 | P10: {=INDEX(pearl!A:A,$K$1+ROW(A10))} -> 46135 | Q10: {=INDEX(pearl!I:I,$K$1+ROW(I10))} -> 36.5
L11: {=INDEX(amber!A:A,$K$1+ROW(A11))} -> 46136 | M11: {=INDEX(amber!I:I,$K$1+ROW(I11))} -> 3.7 | N11: {=INDEX(topaz!A:A,$K$1+ROW(A11))} -> 46136 | O11: {=INDEX(topaz!I:I,$K$1+ROW(I11))} -> -13.5 | P11: {=INDEX(pearl!A:A,$K$1+ROW(A11))} -> 46136 | Q11: {=INDEX(pearl!I:I,$K$1+ROW(I11))} -> 37.4
L12: {=INDEX(amber!A:A,$K$1+ROW(A12))} -> 46137 | M12: {=INDEX(amber!I:I,$K$1+ROW(I12))} -> 4.4 | N12: {=INDEX(topaz!A:A,$K$1+ROW(A12))} -> 46137 | O12: {=INDEX(topaz!I:I,$K$1+ROW(I12))} -> -6 | P12: {=INDEX(pearl!A:A,$K$1+ROW(A12))} -> 46137 | Q12: {=INDEX(pearl!I:I,$K$1+ROW(I12))} -> 38.1
L13: {=INDEX(amber!A:A,$K$1+ROW(A13))} -> 46138 | M13: {=INDEX(amber!I:I,$K$1+ROW(I13))} -> 3.8 | N13: {=INDEX(topaz!A:A,$K$1+ROW(A13))} -> 46138 | O13: {=INDEX(topaz!I:I,$K$1+ROW(I13))} -> -5.5 | P13: {=INDEX(pearl!A:A,$K$1+ROW(A13))} -> 46138 | Q13: {=INDEX(pearl!I:I,$K$1+ROW(I13))} -> 31.9
L14: {=INDEX(amber!A:A,$K$1+ROW(A14))} -> 46139 | M14: {=INDEX(amber!I:I,$K$1+ROW(I14))} -> 1.1 | N14: {=INDEX(topaz!A:A,$K$1+ROW(A14))} -> 46139 | O14: {=INDEX(topaz!I:I,$K$1+ROW(I14))} -> -6.6 | P14: {=INDEX(pearl!A:A,$K$1+ROW(A14))} -> 46139 | Q14: {=INDEX(pearl!I:I,$K$1+ROW(I14))} -> 16.8
L15: {=INDEX(amber!A:A,$K$1+ROW(A15))} -> 46140 | M15: {=INDEX(amber!I:I,$K$1+ROW(I15))} -> -30.8 | N15: {=INDEX(topaz!A:A,$K$1+ROW(A15))} -> 46140 | O15: {=INDEX(topaz!I:I,$K$1+ROW(I15))} -> -5.6 | P15: {=INDEX(pearl!A:A,$K$1+ROW(A15))} -> 46140 | Q15: {=INDEX(pearl!I:I,$K$1+ROW(I15))} -> 5.8
L16: {=INDEX(amber!A:A,$K$1+ROW(A16))} -> 46141 | M16: {=INDEX(amber!I:I,$K$1+ROW(I16))} -> -10.2 | N16: {=INDEX(topaz!A:A,$K$1+ROW(A16))} -> 46141 | O16: {=INDEX(topaz!I:I,$K$1+ROW(I16))} -> -11.4 | P16: {=INDEX(pearl!A:A,$K$1+ROW(A16))} -> 46141 | Q16: {=INDEX(pearl!I:I,$K$1+ROW(I16))} -> 13.2
... L21: {=INDEX(amber!A:A,$K$1+ROW(A21))} -> 0 | M21: {=INDEX(amber!I:I,$K$1+ROW(I21))} -> 0 | N21: {=INDEX(topaz!A:A,$K$1+ROW(A21))} -> 46146 | O21: {=INDEX(topaz!I:I,$K$1+ROW(I21))} -> -8 | P21: {=INDEX(pearl!A:A,$K$1+ROW(A21))} -> 46146 | Q21: {=INDEX(pearl!I:I,$K$1+ROW(I21))} -> 14.3

Sheet form norm refined
A1: Dynamic Normalization Formulas Summary
A3: These formulas create a scrollable, normalized view of discrepancy data.
A4: Row 2 always shows 0, and all other values are relative to the baseline (first visible row).
A5: K1 controls the scroll position (0-based: 0, 1, 2, 3...)
A7: Column | B7: Purpose | C7: Formula
A8: S (Date_Amber) | B8: Shows date shifted by scroll position | C8: {=IF($K$1+ROW()-1>COUNTA($L$2:$L$200),"",INDEX($L$2:$L$200,$K$1+ROW()-1))}
A9: T (Norm_Amber) | B9: Normalized discrepancy (baseline = 0) | C9: {=IF($K$1+ROW()-1>COUNTA($M$2:$M$200),"",INDEX($M$2:$M$200,$K$1+ROW()-1)-INDEX($M$2:$M$200,$K$1+1))}
A10: U (Date_Topaz) | B10: Shows date shifted by scroll position | C10: {=IF($K$1+ROW()-1>COUNTA($N$2:$N$200),"",INDEX($N$2:$N$200,$K$1+ROW()-1))}
A11: V (Norm_Topaz) | B11: Normalized discrepancy (baseline = 0) | C11: {=IF($K$1+ROW()-1>COUNTA($O$2:$O$200),"",INDEX($O$2:$O$200,$K$1+ROW()-1)-INDEX($O$2:$O$200,$K$1+1))}
A12: W (Date_Pearl) | B12: Shows date shifted by scroll position | C12: {=IF($K$1+ROW()-1>COUNTA($P$2:$P$200),"",INDEX($P$2:$P$200,$K$1+ROW()-1))}
A13: X (Norm_Pearl) | B13: Normalized discrepancy (baseline = 0) | C13: {=IF($K$1+ROW()-1>COUNTA($Q$2:$Q$200),"",INDEX($Q$2:$Q$200,$K$1+ROW()-1)-INDEX($Q$2:$Q$200,$K$1+1))}
A15: How It Works:
A16: 1. COUNTA($L$2:$L$200) - Counts actual data rows in the source column | B16: IF($K$1+ROW()-1>COUNTA($L$2:$L$200),"",INDEX($L$2:$L$200,$K$1+ROW()-1))
A17: 2. $K$1+ROW()-1 - Calculates which row of source data to retrieve | B17: IF($K$1+ROW()-1>COUNTA($M$2:$M$200),"",INDEX($M$2:$M$200,$K$1+ROW()-1)-INDEX($M$2:$M$200,$K$1+1))
A18: 3. IF(...>COUNTA(...),"",...) - Returns blank if scrolled past data (prevents #REF! errors)
A19: 4. INDEX(...,$K$1+ROW()-1) - Gets the value at the calculated row position
A20: 5. INDEX(...,$K$1+1) - Gets the baseline value (first visible row)
A21: 6. Subtracting baseline from each value normalizes data so row 2 = 0
A22: 7. Change K1 value (0, 1, 2, 3...) to scroll through the data
A24: Key Benefits:
A25: • Dynamic - Works with any data size (up to 200 rows per vessel)
A26: • No #REF! errors - Returns blank when scrolling past available data
A27: • Normalized - First visible row always = 0 for easy comparison
A28: • Scrollable - Change K1 to shift the viewing window

Sheet normalise refined
K1: 0 | L1: Date | M1: Discrepancy | N1: Date | O1: Discrepancy | P1: Date | Q1: Discrepancy | S1: Date_Amber | T1: Norm_Amber | U1: Date_Topaz | V1: Norm_Topaz | W1: Date_Pearl | X1: Norm_Pearl
L2: {=INDEX(amber!A:A,$K$1+ROW(A2))} -> 46113 | M2: {=INDEX(amber!I:I,$K$1+ROW(I2))} -> 0 | N2: {=INDEX(topaz!A:A,$K$1+ROW(A2))} -> 46113 | O2: {=INDEX(topaz!I:I,$K$1+ROW(I2))} -> 0 | P2: {=INDEX(pearl!A:A,$K$1+ROW(A2))} -> 46113 | Q2: {=INDEX(pearl!I:I,$K$1+ROW(I2))} -> 0 | S2: {=IF($K$1+ROW()-1>COUNTA($L$2:$L$200),"",INDEX($L$2:$L$200,$K$1+ROW()-1))} -> 46113 | T2: {=IF($K$1+ROW()-1>COUNTA($M$2:$M$200),"",INDEX($M$2:$M$200,$K$1+ROW()-1)-INDEX($M$2:$M$200,$K$1+1))} -> 0 | U2: {=IF($K$1+ROW()-1>COUNTA($N$2:$N$200),"",INDEX($N$2:$N$200,$K$1+ROW()-1))} -> 46113 | V2: {=IF($K$1+ROW()-1>COUNTA($O$2:$O$200),"",INDEX($O$2:$O$200,$K$1+ROW()-1)-INDEX($O$2:$O$200,$K$1+1))} -> 0 | W2: {=IF($K$1+ROW()-1>COUNTA($P$2:$P$200),"",INDEX($P$2:$P$200,$K$1+ROW()-1))} -> 46113 | X2: {=IF($K$1+ROW()-1>COUNTA($Q$2:$Q$200),"",INDEX($Q$2:$Q$200,$K$1+ROW()-1)-INDEX($Q$2:$Q$200,$K$1+1))} -> 0
L3: {=INDEX(amber!A:A,$K$1+ROW(A3))} -> 46114 | M3: {=INDEX(amber!I:I,$K$1+ROW(I3))} -> 9.2 | N3: {=INDEX(topaz!A:A,$K$1+ROW(A3))} -> 46114 | O3: {=INDEX(topaz!I:I,$K$1+ROW(I3))} -> 14.5 | P3: {=INDEX(pearl!A:A,$K$1+ROW(A3))} -> 46114 | Q3: {=INDEX(pearl!I:I,$K$1+ROW(I3))} -> 25.6 | S3: {=IF($K$1+ROW()-1>COUNTA($L$2:$L$200),"",INDEX($L$2:$L$200,$K$1+ROW()-1))} -> 46114 | T3: {=IF($K$1+ROW()-1>COUNTA($M$2:$M$200),"",INDEX($M$2:$M$200,$K$1+ROW()-1)-INDEX($M$2:$M$200,$K$1+1))} -> 9.2 | U3: {=IF($K$1+ROW()-1>COUNTA($N$2:$N$200),"",INDEX($N$2:$N$200,$K$1+ROW()-1))} -> 46114 | V3: {=IF($K$1+ROW()-1>COUNTA($O$2:$O$200),"",INDEX($O$2:$O$200,$K$1+ROW()-1)-INDEX($O$2:$O$200,$K$1+1))} -> 14.5 | W3: {=IF($K$1+ROW()-1>COUNTA($P$2:$P$200),"",INDEX($P$2:$P$200,$K$1+ROW()-1))} -> 46114 | X3: {=IF($K$1+ROW()-1>COUNTA($Q$2:$Q$200),"",INDEX($Q$2:$Q$200,$K$1+ROW()-1)-INDEX($Q$2:$Q$200,$K$1+1))} -> 25.6
L4: {=INDEX(amber!A:A,$K$1+ROW(A4))} -> 46115 | M4: {=INDEX(amber!I:I,$K$1+ROW(I4))} -> 34.8 | N4: {=INDEX(topaz!A:A,$K$1+ROW(A4))} -> 46115 | O4: {=INDEX(topaz!I:I,$K$1+ROW(I4))} -> 3.5 | P4: {=INDEX(pearl!A:A,$K$1+ROW(A4))} -> 46115 | Q4: {=INDEX(pearl!I:I,$K$1+ROW(I4))} -> 28.6 | S4: {=IF($K$1+ROW()-1>COUNTA($L$2:$L$200),"",INDEX($L$2:$L$200,$K$1+ROW()-1))} -> 46115 | T4: {=IF($K$1+ROW()-1>COUNTA($M$2:$M$200),"",INDEX($M$2:$M$200,$K$1+ROW()-1)-INDEX($M$2:$M$200,$K$1+1))} -> 34.8 | U4: {=IF($K$1+ROW()-1>COUNTA($N$2:$N$200),"",INDEX($N$2:$N$200,$K$1+ROW()-1))} -> 46115 | V4: {=IF($K$1+ROW()-1>COUNTA($O$2:$O$200),"",INDEX($O$2:$O$200,$K$1+ROW()-1)-INDEX($O$2:$O$200,$K$1+1))} -> 3.5 | W4: {=IF($K$1+ROW()-1>COUNTA($P$2:$P$200),"",INDEX($P$2:$P$200,$K$1+ROW()-1))} -> 46115 | X4: {=IF($K$1+ROW()-1>COUNTA($Q$2:$Q$200),"",INDEX($Q$2:$Q$200,$K$1+ROW()-1)-INDEX($Q$2:$Q$200,$K$1+1))} -> 28.6
L5: {=INDEX(amber!A:A,$K$1+ROW(A5))} -> 46116 | M5: {=INDEX(amber!I:I,$K$1+ROW(I5))} -> -20.4 | N5: {=INDEX(topaz!A:A,$K$1+ROW(A5))} -> 46116 | O5: {=INDEX(topaz!I:I,$K$1+ROW(I5))} -> -11.8 | P5: {=INDEX(pearl!A:A,$K$1+ROW(A5))} -> 46116 | Q5: {=INDEX(pearl!I:I,$K$1+ROW(I5))} -> 49 | S5: {=IF($K$1+ROW()-1>COUNTA($L$2:$L$200),"",INDEX($L$2:$L$200,$K$1+ROW()-1))} -> 46116 | T5: {=IF($K$1+ROW()-1>COUNTA($M$2:$M$200),"",INDEX($M$2:$M$200,$K$1+ROW()-1)-INDEX($M$2:$M$200,$K$1+1))} -> -20.4 | U5: {=IF($K$1+ROW()-1>COUNTA($N$2:$N$200),"",INDEX($N$2:$N$200,$K$1+ROW()-1))} -> 46116 | V5: {=IF($K$1+ROW()-1>COUNTA($O$2:$O$200),"",INDEX($O$2:$O$200,$K$1+ROW()-1)-INDEX($O$2:$O$200,$K$1+1))} -> -11.8 | W5: {=IF($K$1+ROW()-1>COUNTA($P$2:$P$200),"",INDEX($P$2:$P$200,$K$1+ROW()-1))} -> 46116 | X5: {=IF($K$1+ROW()-1>COUNTA($Q$2:$Q$200),"",INDEX($Q$2:$Q$200,$K$1+ROW()-1)-INDEX($Q$2:$Q$200,$K$1+1))} -> 49
L6: {=INDEX(amber!A:A,$K$1+ROW(A6))} -> 46117 | M6: {=INDEX(amber!I:I,$K$1+ROW(I6))} -> -17.2 | N6: {=INDEX(topaz!A:A,$K$1+ROW(A6))} -> 46117 | O6: {=INDEX(topaz!I:I,$K$1+ROW(I6))} -> -13 | P6: {=INDEX(pearl!A:A,$K$1+ROW(A6))} -> 46117 | Q6: {=INDEX(pearl!I:I,$K$1+ROW(I6))} -> 45.4 | S6: {=IF($K$1+ROW()-1>COUNTA($L$2:$L$200),"",INDEX($L$2:$L$200,$K$1+ROW()-1))} -> 46117 | T6: {=IF($K$1+ROW()-1>COUNTA($M$2:$M$200),"",INDEX($M$2:$M$200,$K$1+ROW()-1)-INDEX($M$2:$M$200,$K$1+1))} -> -17.2 | U6: {=IF($K$1+ROW()-1>COUNTA($N$2:$N$200),"",INDEX($N$2:$N$200,$K$1+ROW()-1))} -> 46117 | V6: {=IF($K$1+ROW()-1>COUNTA($O$2:$O$200),"",INDEX($O$2:$O$200,$K$1+ROW()-1)-INDEX($O$2:$O$200,$K$1+1))} -> -13 | W6: {=IF($K$1+ROW()-1>COUNTA($P$2:$P$200),"",INDEX($P$2:$P$200,$K$1+ROW()-1))} -> 46117 | X6: {=IF($K$1+ROW()-1>COUNTA($Q$2:$Q$200),"",INDEX($Q$2:$Q$200,$K$1+ROW()-1)-INDEX($Q$2:$Q$200,$K$1+1))} -> 45.4
L7: {=INDEX(amber!A:A,$K$1+ROW(A7))} -> 46118 | M7: {=INDEX(amber!I:I,$K$1+ROW(I7))} -> -15.2 | N7: {=INDEX(topaz!A:A,$K$1+ROW(A7))} -> 46118 | O7: {=INDEX(topaz!I:I,$K$1+ROW(I7))} -> -16.5 | P7: {=INDEX(pearl!A:A,$K$1+ROW(A7))} -> 46118 | Q7: {=INDEX(pearl!I:I,$K$1+ROW(I7))} -> 45 | S7: {=IF($K$1+ROW()-1>COUNTA($L$2:$L$200),"",INDEX($L$2:$L$200,$K$1+ROW()-1))} -> 46118 | T7: {=IF($K$1+ROW()-1>COUNTA($M$2:$M$200),"",INDEX($M$2:$M$200,$K$1+ROW()-1)-INDEX($M$2:$M$200,$K$1+1))} -> -15.2 | U7: {=IF($K$1+ROW()-1>COUNTA($N$2:$N$200),"",INDEX($N$2:$N$200,$K$1+ROW()-1))} -> 46118 | V7: {=IF($K$1+ROW()-1>COUNTA($O$2:$O$200),"",INDEX($O$2:$O$200,$K$1+ROW()-1)-INDEX($O$2:$O$200,$K$1+1))} -> -16.5 | W7: {=IF($K$1+ROW()-1>COUNTA($P$2:$P$200),"",INDEX($P$2:$P$200,$K$1+ROW()-1))} -> 46118 | X7: {=IF($K$1+ROW()-1>COUNTA($Q$2:$Q$200),"",INDEX($Q$2:$Q$200,$K$1+ROW()-1)-INDEX($Q$2:$Q$200,$K$1+1))} -> 45
L8: {=INDEX(amber!A:A,$K$1+ROW(A8))} -> 46119 | M8: {=INDEX(amber!I:I,$K$1+ROW(I8))} -> -13.9 | N8: {=INDEX(topaz!A:A,$K$1+ROW(A8))} -> 46119 | O8: {=INDEX(topaz!I:I,$K$1+ROW(I8))} -> -9.9 | P8: {=INDEX(pearl!A:A,$K$1+ROW(A8))} -> 46119 | Q8: {=INDEX(pearl!I:I,$K$1+ROW(I8))} -> 44.2 | S8: {=IF($K$1+ROW()-1>COUNTA($L$2:$L$200),"",INDEX($L$2:$L$200,$K$1+ROW()-1))} -> 46119 | T8: {=IF($K$1+ROW()-1>COUNTA($M$2:$M$200),"",INDEX($M$2:$M$200,$K$1+ROW()-1)-INDEX($M$2:$M$200,$K$1+1))} -> -13.9 | U8: {=IF($K$1+ROW()-1>COUNTA($N$2:$N$200),"",INDEX($N$2:$N$200,$K$1+ROW()-1))} -> 46119 | V8: {=IF($K$1+ROW()-1>COUNTA($O$2:$O$200),"",INDEX($O$2:$O$200,$K$1+ROW()-1)-INDEX($O$2:$O$200,$K$1+1))} -> -9.9 | W8: {=IF($K$1+ROW()-1>COUNTA($P$2:$P$200),"",INDEX($P$2:$P$200,$K$1+ROW()-1))} -> 46119 | X8: {=IF($K$1+ROW()-1>COUNTA($Q$2:$Q$200),"",INDEX($Q$2:$Q$200,$K$1+ROW()-1)-INDEX($Q$2:$Q$200,$K$1+1))} -> 44.2
L9: {=INDEX(amber!A:A,$K$1+ROW(A9))} -> 46120 | M9: {=INDEX(amber!I:I,$K$1+ROW(I9))} -> -24.2 | N9: {=INDEX(topaz!A:A,$K$1+ROW(A9))} -> 46120 | O9: {=INDEX(topaz!I:I,$K$1+ROW(I9))} -> -10.3 | P9: {=INDEX(pearl!A:A,$K$1+ROW(A9))} -> 46120 | Q9: {=INDEX(pearl!I:I,$K$1+ROW(I9))} -> 44.1 | S9: {=IF($K$1+ROW()-1>COUNTA($L$2:$L$200),"",INDEX($L$2:$L$200,$K$1+ROW()-1))} -> 46120 | T9: {=IF($K$1+ROW()-1>COUNTA($M$2:$M$200),"",INDEX($M$2:$M$200,$K$1+ROW()-1)-INDEX($M$2:$M$200,$K$1+1))} -> -24.2 | U9: {=IF($K$1+ROW()-1>COUNTA($N$2:$N$200),"",INDEX($N$2:$N$200,$K$1+ROW()-1))} -> 46120 | V9: {=IF($K$1+ROW()-1>COUNTA($O$2:$O$200),"",INDEX($O$2:$O$200,$K$1+ROW()-1)-INDEX($O$2:$O$200,$K$1+1))} -> -10.3 | W9: {=IF($K$1+ROW()-1>COUNTA($P$2:$P$200),"",INDEX($P$2:$P$200,$K$1+ROW()-1))} -> 46120 | X9: {=IF($K$1+ROW()-1>COUNTA($Q$2:$Q$200),"",INDEX($Q$2:$Q$200,$K$1+ROW()-1)-INDEX($Q$2:$Q$200,$K$1+1))} -> 44.1
L10: {=INDEX(amber!A:A,$K$1+ROW(A10))} -> 46121 | M10: {=INDEX(amber!I:I,$K$1+ROW(I10))} -> -20.7 | N10: {=INDEX(topaz!A:A,$K$1+ROW(A10))} -> 46121 | O10: {=INDEX(topaz!I:I,$K$1+ROW(I10))} -> -9.5 | P10: {=INDEX(pearl!A:A,$K$1+ROW(A10))} -> 46121 | Q10: {=INDEX(pearl!I:I,$K$1+ROW(I10))} -> 40 | S10: {=IF($K$1+ROW()-1>COUNTA($L$2:$L$200),"",INDEX($L$2:$L$200,$K$1+ROW()-1))} -> 46121 | T10: {=IF($K$1+ROW()-1>COUNTA($M$2:$M$200),"",INDEX($M$2:$M$200,$K$1+ROW()-1)-INDEX($M$2:$M$200,$K$1+1))} -> -20.7 | U10: {=IF($K$1+ROW()-1>COUNTA($N$2:$N$200),"",INDEX($N$2:$N$200,$K$1+ROW()-1))} -> 46121 | V10: {=IF($K$1+ROW()-1>COUNTA($O$2:$O$200),"",INDEX($O$2:$O$200,$K$1+ROW()-1)-INDEX($O$2:$O$200,$K$1+1))} -> -9.5 | W10: {=IF($K$1+ROW()-1>COUNTA($P$2:$P$200),"",INDEX($P$2:$P$200,$K$1+ROW()-1))} -> 46121 | X10: {=IF($K$1+ROW()-1>COUNTA($Q$2:$Q$200),"",INDEX($Q$2:$Q$200,$K$1+ROW()-1)-INDEX($Q$2:$Q$200,$K$1+1))} -> 40
